Workbook

Sheet Input
B2: Description | C2: Unit | D2: 4000
B3: Project Reference | C3: Unique | D3: =D4&D30 -> 44293
B4: Date | C4: Calculation | D4: =TODAY() -> 44293 | G4: EAC
B5: Electricity Demand | C5: Annual kWh | D5: 4000 | F5: Standard Model
B6: Price of Electricity | C6: Per kWh | D6: 0.17556 | F6: Beds | G6: 2 | H6: 3 | I6: 4 | J6: 5 | K6: 6
B7: Standing Charge | C7: Per Day | D7: 0.2226 | F7: Low User | G7: 2000 | H7: 3000 | I7: 4150 | J7: 4500 | K7: 4750
B8: Annual Cost of Electricity | C8: Calculation | D8: =(D5*D6)+(D7*365) -> 783.489 | F8: Std User | G8: 2500 | H8: 3500 | I8: 4650 | J8: 5000 | K8: 5250
B9: Quantity of Panels | C9: Number | D9: 9 | F9: High User | G9: 3500 | H9: 4500 | I9: 5650 | J9: 6000 | K9: 6250
B10: Panel Manufacturer | C10: Option | D10: Trina | F10: Add Below to above EAC if Required
B11: Panel Wattage | C11: Option | D11: 330 | F11: Electric Car | G11: 2500
B12: System Size | C12: Calculated kW dc | D12: =(D9*D11)/1000 -> 2.97 | F12: Air Source Heating | G12: 3000
B13: Specific Yield | C13: Annual kWh per KW | D13: 927 | F13: Swimming Pool (Electric) | G13: 3500
B14: Shading Factor | C14: SF | D14: =100%-('MCS Shading Check'!S28) -> 0.95 | F14: Electricity Rates
B15: Annual Yield | C15: Calculation | D15: =(D13*D12)*D14 -> 2615.5305 | G15: Rate | H15: VAT | I15: Total
B16: Irradience Zone | C16: As per MCS Guide | D16: =VLOOKUP(D23,'MCS Irradiation Zones'!AN2:AO370,2,0) -> 3 | F16: Average UK Electricity Rate | G16: 0.1672 | H16: =G16*0.05 -> 0.00836 | I16: =G16+H16 -> 0.17556
B17: Roof Pitch (Degrees) | C17: ⁰ | D17: 35 | F17: Average UK Standing Charge | G17: 0.212 | H17: =G17*0.05 -> 0.0106 | I17: =G17+H17 -> 0.2226
B18: Azimuth(Degrees) | C18: ⁰ | D18: 30 | I18: Use Above if Unknown
B19: Roof Type | C19: Option | D19: Concrete
B20: Panels | C20: Option | D20: Black
B21: Scaffold Required | C21: Option | D21: No
B22: Storage Size | C22: kW dc | D22: 5
B23: Postcode (Short) | C23: Option | D23: SP9
B24: Title | C24: Text
B25: First Name | C25: Text
B26: Last Name | C26: Text
B27: House Number | C27: Text
B28: Street Name | C28: Text
B29: Town | C29: Text
B30: Postcode | C30: Text
B31: Telephone Number | C31: Number
B32: Salesman Discount | C32: Select | D32: 0
B33: Main Margin | C33: Select | D33: 0.5
B34: FInal Margin | C34: % | D34: =D33-D32 -> 0.5
B35: VAT Level | C35: % | D35: 0.05
B36: Additional Item | C36: Choice | D36: Solar Edge
B37: Additional Item | C37: Choice | D37: None
B38: Additional Item | C38: Choice | D38: None | F38: System Size Bigger than 4kW | G38: Grid Application
B39: Additional Item | C39: Choice | D39: None | F39: System Size Bigger than 5kW | G39: Grid Application 2
F40: System Size Bigger > 4kW but <5kW | G40: Sofar Solar 4000 HYD Hybrid Inverter
F41: System Size Bigger > 5kW but <6kW | G41: Sofar Solar 5000 HYD Hybrid Inverter
...

Sheet MCS Irradiation Zones
C1: Inclination (variation from horizontal)
A2: Zone | B2: Slope | C2: 0 | D2: 5 | E2: 10 | F2: 15 | G2: 20 | H2: 25 | I2: 30 | J2: 35 | K2: 40 | L2: 45 | M2: 50 | N2: 55 | O2: 60 | P2: 65 | Q2: 70 | R2: 75 | S2: 80 | T2: 85 | U2: 90 | V2: 95 | W2: 100 | X2: 105 | Y2: 110 | Z2: 115 | AA2: 120 | AB2: 125 | AC2: 130 | AD2: 135 | AE2: 140 | AF2: 145 | AG2: 150 | AH2: 155 | AI2: 160 | AJ2: 165 | AK2: 170 | AL2: 175 | AN2: AB | AO2: 16
A3: 1 | B3: 0 | C3: 828 | D3: 828 | E3: 828 | F3: 828 | G3: 828 | H3: 828 | I3: 828 | J3: 828 | K3: 828 | L3: 828 | M3: 828 | N3: 828 | O3: 828 | P3: 828 | Q3: 828 | R3: 828 | S3: 828 | T3: 828 | U3: 828 | V3: 828 | W3: 828 | X3: 828 | Y3: 828 | Z3: 828 | AA3: 828 | AB3: 828 | AC3: 828 | AD3: 828 | AE3: 828 | AF3: 828 | AG3: 828 | AH3: 828 | AI3: 828 | AJ3: 828 | AK3: 828 | AL3: 828 | AN3: AL | AO3: 1
A4: 1 | B4: 1 | C4: 835 | D4: 835 | E4: 835 | F4: 835 | G4: 835 | H4: 835 | I4: 834 | J4: 834 | K4: 833 | L4: 833 | M4: 833 | N4: 832 | O4: 831 | P4: 831 | Q4: 830 | R4: 830 | S4: 829 | T4: 828 | U4: 828 | V4: 827 | W4: 826 | X4: 826 | Y4: 825 | Z4: 824 | AA4: 824 | AB4: 823 | AC4: 823 | AD4: 822 | AE4: 822 | AF4: 821 | AG4: 821 | AH4: 821 | AI4: 820 | AJ4: 820 | AK4: 820 | AL4: 820 | AN4: B | AO4: 6
A5: 1 | B5: 2 | C5: 843 | D5: 843 | E5: 843 | F5: 842 | G5: 842 | H5: 841 | I5: 841 | J5: 840 | K5: 839 | L5: 838 | M5: 837 | N5: 836 | O5: 835 | P5: 834 | Q5: 833 | R5: 831 | S5: 830 | T5: 829 | U5: 827 | V5: 826 | W5: 825 | X5: 823 | Y5: 822 | Z5: 821 | AA5: 820 | AB5: 819 | AC5: 818 | AD5: 817 | AE5: 816 | AF5: 815 | AG5: 814 | AH5: 813 | AI5: 813 | AJ5: 813 | AK5: 812 | AL5: 812 | AN5: BA | AO5: 5E
A6: 1 | B6: 3 | C6: 850 | D6: 850 | E6: 850 | F6: 849 | G6: 849 | H6: 848 | I6: 847 | J6: 846 | K6: 845 | L6: 843 | M6: 842 | N6: 840 | O6: 839 | P6: 837 | Q6: 835 | R6: 833 | S6: 831 | T6: 829 | U6: 827 | V6: 825 | W6: 823 | X6: 821 | Y6: 819 | Z6: 817 | AA6: 816 | AB6: 814 | AC6: 812 | AD6: 811 | AE6: 809 | AF6: 808 | AG6: 807 | AH6: 806 | AI6: 805 | AJ6: 805 | AK6: 804 | AL6: 804 | AN6: BB | AO6: 7E
A7: 1 | B7: 4 | C7: 857 | D7: 857 | E7: 857 | F7: 856 | G7: 855 | H7: 854 | I7: 853 | J7: 852 | K7: 850 | L7: 848 | M7: 846 | N7: 844 | O7: 842 | P7: 840 | Q7: 837 | R7: 835 | S7: 832 | T7: 830 | U7: 827 | V7: 824 | W7: 821 | X7: 819 | Y7: 816 | Z7: 814 | AA7: 811 | AB7: 809 | AC7: 807 | AD7: 805 | AE7: 803 | AF7: 801 | AG7: 800 | AH7: 799 | AI7: 798 | AJ7: 797 | AK7: 796 | AL7: 796 | AN7: BD | AO7: 11
A8: 1 | B8: 5 | C8: 864 | D8: 864 | E8: 864 | F8: 863 | G8: 862 | H8: 861 | I8: 859 | J8: 857 | K8: 855 | L8: 853 | M8: 851 | N8: 848 | O8: 845 | P8: 843 | Q8: 839 | R8: 836 | S8: 833 | T8: 830 | U8: 826 | V8: 823 | W8: 820 | X8: 816 | Y8: 813 | Z8: 810 | AA8: 807 | AB8: 804 | AC8: 802 | AD8: 799 | AE8: 797 | AF8: 795 | AG8: 793 | AH8: 791 | AI8: 790 | AJ8: 789 | AK8: 788 | AL8: 788 | AN8: BD23 | AO8: 10
A9: 1 | B9: 6 | C9: 871 | D9: 871 | E9: 870 | F9: 869 | G9: 868 | H9: 867 | I9: 865 | J9: 863 | K9: 861 | L9: 858 | M9: 855 | N9: 852 | O9: 849 | P9: 845 | Q9: 841 | R9: 838 | S9: 834 | T9: 830 | U9: 826 | V9: 822 | W9: 818 | X9: 814 | Y9: 810 | Z9: 806 | AA9: 803 | AB9: 799 | AC9: 796 | AD9: 793 | AE9: 790 | AF9: 788 | AG9: 786 | AH9: 784 | AI9: 782 | AJ9: 781 | AK9: 780 | AL9: 779 | AN9: BD24 | AO9: 10
A10: 1 | B10: 7 | C10: 878 | D10: 877 | E10: 877 | F10: 876 | G10: 874 | H10: 873 | I10: 871 | J10: 868 | K10: 866 | L10: 862 | M10: 859 | N10: 856 | O10: 852 | P10: 848 | Q10: 843 | R10: 839 | S10: 835 | T10: 830 | U10: 825 | V10: 821 | W10: 816 | X10: 811 | Y10: 807 | Z10: 803 | AA10: 798 | AB10: 794 | AC10: 791 | AD10: 787 | AE10: 784 | AF10: 781 | AG10: 778 | AH10: 776 | AI10: 774 | AJ10: 773 | AK10: 772 | AL10: 771 | AN10: BH | AO10: 3
A11: 1 | B11: 8 | C11: 884 | D11: 884 | E11: 883 | F11: 882 | G11: 881 | H11: 879 | I11: 876 | J11: 873 | K11: 870 | L11: 867 | M11: 863 | N11: 859 | O11: 855 | P11: 850 | Q11: 845 | R11: 840 | S11: 835 | T11: 830 | U11: 825 | V11: 819 | W11: 814 | X11: 809 | Y11: 804 | Z11: 799 | AA11: 794 | AB11: 789 | AC11: 785 | AD11: 781 | AE11: 777 | AF11: 774 | AG11: 771 | AH11: 768 | AI11: 766 | AJ11: 764 | AK11: 763 | AL11: 762 | AN11: BL | AO11: 7E
A12: 1 | B12: 9 | C12: 890 | D12: 890 | E12: 889 | F12: 888 | G12: 886 | H12: 884 | I12: 882 | J12: 878 | K12: 875 | L12: 871 | M12: 867 | N12: 862 | O12: 857 | P12: 852 | Q12: 847 | R12: 841 | S12: 836 | T12: 830 | U12: 824 | V12: 818 | W12: 812 | X12: 806 | Y12: 800 | Z12: 795 | AA12: 789 | AB12: 784 | AC12: 779 | AD12: 775 | AE12: 770 | AF12: 767 | AG12: 763 | AH12: 760 | AI12: 758 | AJ12: 756 | AK12: 755 | AL12: 754 | AN12: BN | AO12: 2
A13: 1 | B13: 10 | C13: 896 | D13: 896 | E13: 895 | F13: 894 | G13: 892 | H13: 890 | I13: 887 | J13: 883 | K13: 880 | L13: 875 | M13: 871 | N13: 866 | O13: 860 | P13: 855 | Q13: 849 | R13: 842 | S13: 836 | T13: 830 | U13: 823 | V13: 817 | W13: 810 | X13: 803 | Y13: 797 | Z13: 791 | AA13: 785 | AB13: 779 | AC13: 773 | AD13: 768 | AE13: 764 | AF13: 760 | AG13: 756 | AH13: 753 | AI13: 750 | AJ13: 748 | AK13: 746 | AL13: 745 | AN13: BR | AO13: 2
A14: 1 | B14: 11 | C14: 902 | D14: 902 | E14: 901 | F14: 900 | G14: 898 | H14: 895 | I14: 892 | J14: 888 | K14: 884 | L14: 879 | M14: 874 | N14: 869 | O14: 863 | P14: 857 | Q14: 850 | R14: 843 | S14: 836 | T14: 829 | U14: 822 | V14: 815 | W14: 808 | X14: 801 | Y14: 794 | Z14: 787 | AA14: 780 | AB14: 774 | AC14: 768 | AD14: 762 | AE14: 757 | AF14: 752 | AG14: 748 | AH14: 745 | AI14: 742 | AJ14: 739 | AK14: 738 | AL14: 737 | AN14: BS | AO14: 5E
A15: 1 | B15: 12 | C15: 908 | D15: 908 | E15: 907 | F15: 905 | G15: 903 | H15: 900 | I15: 897 | J15: 893 | K15: 888 | L15: 883 | M15: 878 | N15: 872 | O15: 865 | P15: 859 | Q15: 852 | R15: 844 | S15: 837 | T15: 829 | U15: 821 | V15: 813 | W15: 806 | X15: 798 | Y15: 790 | Z15: 783 | AA15: 775 | AB15: 769 | AC15: 762 | AD15: 756 | AE15: 750 | AF15: 745 | AG15: 741 | AH15: 737 | AI15: 734 | AJ15: 731 | AK15: 729 | AL15: 728 | AN15: BT | AO15: 21
A16: 1 | B16: 13 | C16: 914 | D16: 913 | E16: 912 | F16: 910 | G16: 908 | H16: 905 | I16: 901 | J16: 897 | K16: 892 | L16: 887 | M16: 881 | N16: 875 | O16: 868 | P16: 861 | Q16: 853 | R16: 845 | S16: 837 | T16: 829 | U16: 820 | V16: 812 | W16: 803 | X16: 795 | Y16: 787 | Z16: 779 | AA16: 771 | AB16: 763 | AC16: 756 | AD16: 750 | AE16: 743 | AF16: 738 | AG16: 733 | AH16: 729 | AI16: 726 | AJ16: 723 | AK16: 721 | AL16: 720 | AN16: CA | AO16: 8E
A17: 1 | B17: 14 | C17: 919 | D17: 919 | E17: 917 | F17: 916 | G17: 913 | H17: 910 | I17: 906 | J17: 901 | K17: 896 | L17: 890 | M17: 884 | N17: 877 | O17: 870 | P17: 862 | Q17: 854 | R17: 846 | S17: 837 | T17: 828 | U17: 819 | V17: 810 | W17: 801 | X17: 792 | Y17: 783 | Z17: 774 | AA17: 766 | AB17: 758 | AC17: 750 | AD17: 743 | AE17: 737 | AF17: 731 | AG17: 726 | AH17: 721 | AI17: 717 | AJ17: 715 | AK17: 713 | AL17: 711 | AN17: CB | AO17: 12
A18: 1 | B18: 15 | C18: 924 | D18: 924 | E18: 922 | F18: 921 | G18: 918 | H18: 914 | I18: 910 | J18: 905 | K18: 900 | L18: 894 | M18: 887 | N18: 880 | O18: 872 | P18: 864 | Q18: 855 | R18: 846 | S18: 837 | T18: 828 | U18: 818 | V18: 809 | W18: 799 | X18: 789 | Y18: 780 | Z18: 770 | AA18: 761 | AB18: 753 | AC18: 745 | AD18: 737 | AE18: 730 | AF18: 724 | AG18: 718 | AH18: 713 | AI18: 709 | AJ18: 707 | AK18: 704 | AL18: 703 | AN18: CF | AO18: 5W
A19: 1 | B19: 16 | C19: 929 | D19: 929 | E19: 927 | F19: 925 | G19: 922 | H19: 919 | I19: 914 | J19: 909 | K19: 903 | L19: 897 | M19: 890 | N19: 882 | O19: 874 | P19: 866 | Q19: 856 | R19: 847 | S19: 837 | T19: 827 | U19: 817 | V19: 807 | W19: 796 | X19: 786 | Y19: 776 | Z19: 766 | AA19: 757 | AB19: 747 | AC19: 739 | AD19: 731 | AE19: 723 | AF19: 716 | AG19: 711 | AH19: 706 | AI19: 702 | AJ19: 698 | AK19: 697 | AL19: 695 | AN19: CH | AO19: 7E
A20: 1 | B20: 17 | C20: 934 | D20: 933 | E20: 932 | F20: 930 | G20: 927 | H20: 923 | I20: 918 | J20: 913 | K20: 907 | L20: 900 | M20: 893 | N20: 885 | O20: 876 | P20: 867 | Q20: 857 | R20: 848 | S20: 837 | T20: 827 | U20: 816 | V20: 805 | W20: 794 | X20: 783 | Y20: 773 | Z20: 762 | AA20: 752 | AB20: 742 | AC20: 733 | AD20: 724 | AE20: 716 | AF20: 709 | AG20: 703 | AH20: 698 | AI20: 694 | AJ20: 691 | AK20: 688 | AL20: 687 | AN20: CH5 | AO20: 7W
A21: 1 | B21: 18 | C21: 938 | D21: 938 | E21: 936 | F21: 934 | G21: 931 | H21: 927 | I21: 922 | J21: 917 | K21: 910 | L21: 903 | M21: 895 | N21: 887 | O21: 878 | P21: 868 | Q21: 858 | R21: 848 | S21: 837 | T21: 826 | U21: 815 | V21: 803 | W21: 792 | X21: 780 | Y21: 769 | Z21: 758 | AA21: 747 | AB21: 737 | AC21: 727 | AD21: 718 | AE21: 710 | AF21: 702 | AG21: 696 | AH21: 690 | AI21: 686 | AJ21: 683 | AK21: 680 | AL21: 679 | AN21: CH6 | AO21: 7W
A22: 1 | B22: 19 | C22: 943 | D22: 942 | E22: 941 | F22: 938 | G22: 935 | H22: 931 | I22: 926 | J22: 920 | K22: 913 | L22: 906 | M22: 898 | N22: 889 | O22: 879 | P22: 870 | Q22: 859 | R22: 848 | S22: 837 | T22: 825 | U22: 813 | V22: 802 | W22: 790 | X22: 777 | Y22: 766 | Z22: 754 | AA22: 742 | AB22: 732 | AC22: 721 | AD22: 712 | AE22: 703 | AF22: 695 | AG22: 688 | AH22: 683 | AI22: 678 | AJ22: 675 | AK22: 672 | AL22: 671 | AN22: CH7 | AO22: 7W
A23: 1 | B23: 20 | C23: 947 | D23: 946 | E23: 945 | F23: 942 | G23: 939 | H23: 935 | I23: 929 | J23: 923 | K23: 916 | L23: 908 | M23: 900 | N23: 891 | O23: 881 | P23: 870 | Q23: 859 | R23: 848 | S23: 836 | T23: 824 | U23: 812 | V23: 799 | W23: 787 | X23: 774 | Y23: 762 | Z23: 750 | AA23: 738 | AB23: 726 | AC23: 716 | AD23: 705 | AE23: 696 | AF23: 688 | AG23: 681 | AH23: 675 | AI23: 671 | AJ23: 667 | AK23: 664 | AL23: 663 | AN23: CH8 | AO23: 7W
A24: 1 | B24: 21 | C24: 951 | D24: 950 | E24: 949 | F24: 946 | G24: 943 | H24: 938 | I24: 933 | J24: 926 | K24: 919 | L24: 911 | M24: 902 | N24: 893 | O24: 882 | P24: 871 | Q24: 860 | R24: 848 | S24: 836 | T24: 823 | U24: 811 | V24: 798 | W24: 784 | X24: 771 | Y24: 758 | Z24: 745 | AA24: 733 | AB24: 721 | AC24: 710 | AD24: 699 | AE24: 690 | AF24: 681 | AG24: 674 | AH24: 668 | AI24: 663 | AJ24: 659 | AK24: 657 | AL24: 655 | AN24: CM | AO24: 12
A25: 1 | B25: 22 | C25: 954 | D25: 954 | E25: 952 | F25: 950 | G25: 946 | H25: 941 | I25: 936 | J25: 929 | K25: 922 | L25: 913 | M25: 904 | N25: 894 | O25: 883 | P25: 872 | Q25: 860 | R25: 848 | S25: 835 | T25: 822 | U25: 809 | V25: 795 | W25: 782 | X25: 768 | Y25: 755 | Z25: 742 | AA25: 729 | AB25: 716 | AC25: 704 | AD25: 693 | AE25: 683 | AF25: 674 | AG25: 667 | AH25: 660 | AI25: 655 | AJ25: 651 | AK25: 648 | AL25: 646 | AN25: CM21 | AO25: 1
A26: 1 | B26: 23 | C26: 958 | D26: 957 | E26: 956 | F26: 953 | G26: 949 | H26: 944 | I26: 939 | J26: 932 | K26: 924 | L26: 915 | M26: 906 | N26: 896 | O26: 885 | P26: 873 | Q26: 861 | R26: 848 | S26: 835 | T26: 821 | U26: 807 | V26: 794 | W26: 779 | X26: 765 | Y26: 751 | Z26: 737 | AA26: 724 | AB26: 711 | AC26: 698 | AD26: 687 | AE26: 676 | AF26: 667 | AG26: 659 | AH26: 653 | AI26: 648 | AJ26: 643 | AK26: 640 | AL26: 638 | AN26: CM22 | AO26: 1
A27: 1 | B27: 24 | C27: 961 | D27: 961 | E27: 959 | F27: 956 | G27: 952 | H27: 947 | I27: 941 | J27: 934 | K27: 926 | L27: 917 | M27: 907 | N27: 897 | O27: 886 | P27: 873 | Q27: 861 | R27: 848 | S27: 834 | T27: 820 | U27: 806 | V27: 791 | W27: 777 | X27: 762 | Y27: 748 | Z27: 733 | AA27: 719 | AB27: 706 | AC27: 693 | AD27: 681 | AE27: 670 | AF27: 660 | AG27: 652 | AH27: 645 | AI27: 640 | AJ27: 635 | AK27: 632 | AL27: 630 | AN27: CM23 | AO27: 1
A28: 1 | B28: 25 | C28: 964 | D28: 964 | E28: 962 | F28: 959 | G28: 955 | H28: 950 | I28: 944 | J28: 937 | K28: 928 | L28: 919 | M28: 909 | N28: 898 | O28: 886 | P28: 874 | Q28: 861 | R28: 847 | S28: 833 | T28: 819 | U28: 804 | V28: 789 | W28: 774 | X28: 759 | Y28: 744 | Z28: 729 | AA28: 714 | AB28: 700 | AC28: 687 | AD28: 675 | AE28: 663 | AF28: 653 | AG28: 645 | AH28: 638 | AI28: 632 | AJ28: 627 | AK28: 623 | AL28: 621 | AN28: CO | AO28: 12
A29: 1 | B29: 26 | C29: 967 | D29: 967 | E29: 965 | F29: 962 | G29: 958 | H29: 953 | I29: 946 | J29: 939 | K29: 930 | L29: 921 | M29: 910 | N29: 899 | O29: 887 | P29: 874 | Q29: 861 | R29: 847 | S29: 833 | T29: 818 | U29: 802 | V29: 787 | W29: 772 | X29: 756 | Y29: 740 | Z29: 725 | AA29: 710 | AB29: 695 | AC29: 682 | AD29: 668 | AE29: 657 | AF29: 646 | AG29: 638 | AH29: 630 | AI29: 624 | AJ29: 619 | AK29: 615 | AL29: 614 | AN29: CR | AO29: 1
A30: 1 | B30: 27 | C30: 970 | D30: 969 | E30: 968 | F30: 965 | G30: 960 | H30: 955 | I30: 948 | J30: 941 | K30: 932 | L30: 922 | M30: 911 | N30: 900 | O30: 887 | P30: 874 | Q30: 861 | R30: 846 | S30: 831 | T30: 816 | U30: 801 | V30: 785 | W30: 769 | X30: 752 | Y30: 737 | Z30: 721 | AA30: 705 | AB30: 690 | AC30: 676 | AD30: 662 | AE30: 650 | AF30: 640 | AG30: 630 | AH30: 623 | AI30: 616 | AJ30: 611 | AK30: 608 | AL30: 605 | AN30: CT | AO30: 2
A31: 1 | B31: 28 | C31: 972 | D31: 972 | E31: 970 | F31: 967 | G31: 962 | H31: 957 | I31: 950 | J31: 942 | K31: 933 | L31: 923 | M31: 912 | N31: 900 | O31: 888 | P31: 874 | Q31: 860 | R31: 845 | S31: 830 | T31: 815 | U31: 799 | V31: 782 | W31: 766 | X31: 749 | Y31: 733 | Z31: 717 | AA31: 701 | AB31: 685 | AC31: 670 | AD31: 656 | AE31: 644 | AF31: 633 | AG31: 623 | AH31: 615 | AI31: 608 | AJ31: 603 | AK31: 599 | AL31: 597 | AN31: CV | AO31: 6
A32: 1 | B32: 29 | C32: 975 | D32: 974 | E32: 972 | F32: 969 | G32: 964 | H32: 959 | I32: 952 | J32: 944 | K32: 935 | L32: 924 | M32: 913 | N32: 901 | O32: 888 | P32: 874 | Q32: 860 | R32: 845 | S32: 829 | T32: 813 | U32: 797 | V32: 780 | W32: 763 | X32: 746 | Y32: 729 | Z32: 712 | AA32: 696 | AB32: 680 | AC32: 665 | AD32: 651 | AE32: 637 | AF32: 626 | AG32: 616 | AH32: 608 | AI32: 600 | AJ32: 595 | AK32: 591 | AL32: 589 | AN32: CW | AO32: 7E
A33: 1 | B33: 30 | C33: 977 | D33: 976 | E33: 974 | F33: 971 | G33: 966 | H33: 960 | I33: 953 | J33: 945 | K33: 936 | L33: 925 | M33: 914 | N33: 901 | O33: 888 | P33: 874 | Q33: 859 | R33: 844 | S33: 828 | T33: 811 | U33: 795 | V33: 777 | W33: 760 | X33: 743 | Y33: 725 | Z33: 708 | AA33: 691 | AB33: 675 | AC33: 659 | AD33: 644 | AE33: 631 | AF33: 619 | AG33: 609 | AH33: 600 | AI33: 593 | AJ33: 587 | AK33: 583 | AL33: 581 | AN33: DA | AO33: 2
A34: 1 | B34: 31 | C34: 979 | D34: 978 | E34: 976 | F34: 973 | G34: 968 | H34: 962 | I34: 955 | J34: 946 | K34: 937 | L34: 926 | M34: 914 | N34: 901 | O34: 888 | P34: 873 | Q34: 858 | R34: 843 | S34: 826 | T34: 810 | U34: 792 | V34: 775 | W34: 757 | X34: 739 | Y34: 722 | Z34: 704 | AA34: 687 | AB34: 670 | AC34: 654 | AD34: 639 | AE34: 625 | AF34: 612 | AG34: 602 | AH34: 593 | AI34: 585 | AJ34: 579 | AK34: 575 | AL34: 573 | AN34: DD | AO34: 15
A35: 1 | B35: 32 | C35: 980 | D35: 979 | E35: 977 | F35: 974 | G35: 969 | H35: 963 | I35: 956 | J35: 947 | K35: 937 | L35: 926 | M35: 914 | N35: 901 | O35: 888 | P35: 873 | Q35: 857 | R35: 841 | S35: 825 | T35: 808 | U35: 790 | V35: 772 | W35: 754 | X35: 736 | Y35: 718 | Z35: 700 | AA35: 682 | AB35: 665 | AC35: 648 | AD35: 633 | AE35: 618 | AF35: 606 | AG35: 595 | AH35: 585 | AI35: 577 | AJ35: 571 | AK35: 568 | AL35: 565 | AN35: DE | AO35: 6
A36: 1 | B36: 33 | C36: 982 | D36: 981 | E36: 979 | F36: 975 | G36: 970 | H36: 964 | I36: 957 | J36: 948 | K36: 938 | L36: 927 | M36: 914 | N36: 901 | O36: 887 | P36: 872 | Q36: 856 | R36: 840 | S36: 823 | T36: 806 | U36: 788 | V36: 769 | W36: 751 | X36: 733 | Y36: 714 | Z36: 696 | AA36: 678 | AB36: 660 | AC36: 643 | AD36: 627 | AE36: 612 | AF36: 599 | AG36: 588 | AH36: 578 | AI36: 570 | AJ36: 564 | AK36: 560 | AL36: 557 | AN36: DG | AO36: 8S
A37: 1 | B37: 34 | C37: 983 | D37: 982 | E37: 980 | F37: 976 | G37: 971 | H37: 965 | I37: 957 | J37: 948 | K37: 938 | L37: 927 | M37: 914 | N37: 901 | O37: 886 | P37: 871 | Q37: 855 | R37: 838 | S37: 821 | T37: 803 | U37: 785 | V37: 767 | W37: 748 | X37: 729 | Y37: 710 | Z37: 691 | AA37: 673 | AB37: 655 | AC37: 638 | AD37: 621 | AE37: 606 | AF37: 592 | AG37: 581 | AH37: 570 | AI37: 562 | AJ37: 556 | AK37: 551 | AL37: 548 | AN37: DH | AO37: 10
A38: 1 | B38: 35 | C38: 984 | D38: 983 | E38: 981 | F38: 977 | G38: 972 | H38: 966 | I38: 958 | J38: 949 | K38: 938 | L38: 927 | M38: 914 | N38: 900 | O38: 886 | P38: 870 | Q38: 854 | R38: 837 | S38: 819 | T38: 801 | U38: 783 | V38: 764 | W38: 745 | X38: 726 | Y38: 706 | Z38: 687 | AA38: 668 | AB38: 650 | AC38: 632 | AD38: 616 | AE38: 600 | AF38: 586 | AG38: 573 | AH38: 563 | AI38: 555 | AJ38: 548 | AK38: 543 | AL38: 540 | AN38: DH4 | AO38: 9E
A39: 1 | B39: 36 | C39: 984 | D39: 984 | E39: 981 | F39: 978 | G39: 973 | H39: 966 | I39: 958 | J39: 949 | K39: 938 | L39: 927 | M39: 914 | N39: 900 | O39: 885 | P39: 869 | Q39: 852 | R39: 835 | S39: 817 | T39: 799 | U39: 780 | V39: 761 | W39: 741 | X39: 722 | Y39: 702 | Z39: 683 | AA39: 664 | AB39: 645 | AC39: 627 | AD39: 610 | AE39: 594 | AF39: 579 | AG39: 566 | AH39: 556 | AI39: 547 | AJ39: 540 | AK39: 535 | AL39: 532 | AN39: DH5 | AO39: 9E
A40: 1 | B40: 37 | C40: 985 | D40: 984 | E40: 982 | F40: 978 | G40: 973 | H40: 966 | I40: 958 | J40: 949 | K40: 938 | L40: 926 | M40: 913 | N40: 899 | O40: 884 | P40: 868 | Q40: 851 | R40: 833 | S40: 815 | T40: 796 | U40: 777 | V40: 758 | W40: 738 | X40: 718 | Y40: 698 | Z40: 679 | AA40: 659 | AB40: 640 | AC40: 622 | AD40: 604 | AE40: 588 | AF40: 572 | AG40: 560 | AH40: 549 | AI40: 540 | AJ40: 533 | AK40: 528 | AL40: 524 | AN40: DL | AO40: 10
...

Sheet MCS Shading Check
S1: For every cell effected by shading in the sunpath of the array we need to allow for a 1% shading loss in the cell below.
S28: 0.05

Sheet Online Sales Pack
A1: Your Quotation (Inclusive of VAT)
A2: =Costing!L37 -> 6271.0814
A3: PAYMENT TERMS
A4: Payment 1 @ 25% placing an order | H4: =A2*25% -> 1567.7703
A5: Payment 2 @ 75% upon completion | H5: =A2*75% -> 4703.311
A7: System Size (kWdc) | H7: =Costing!C1 -> 2.97
A8: Quantity of Panels | H8: =Input!D9&" Panels" -> 9 Panels
A9: Battery Storage Size | H9: =Input!D22&" kWdc" -> 5 kWdc
A10: BREAKDOWN OF PERFORMANCE
A11: Description | B11: Jan | C11: Feb | D11: Mar | E11: Apr | F11: May | G11: Jun | H11: Jul | I11: Aug | J11: Sept | K11: Oct | L11: Nov | M11: Dec | N11: Total
A12: Grid Usage | B12: =Calculation!KM3 -> 404.98144 | C12: =Calculation!KN3 -> 354.12301 | D12: =Calculation!KO3 -> 360.96353 | E12: =Calculation!KP3 -> 311.90745 | F12: =Calculation!KQ3 -> 299.67844 | G12: =Calculation!KR3 -> 276.31457 | H12: =Calculation!KS3 -> 281.96008 | I12: =Calculation!KT3 -> 286.79034 | ... M12: =Calculation!KX3 -> 413.68648 | N12: =SUM(B12:M12) -> 4000
A13: Solar Generation | B13: =Calculation!KM4 -> 74.555197 | C13: =Calculation!KN4 -> 138.97343 | D13: =Calculation!KO4 -> 224.34175 | E13: =Calculation!KP4 -> 307.95021 | F13: =Calculation!KQ4 -> 383.82271 | G13: =Calculation!KR4 -> 301.31171 | H13: =Calculation!KS4 -> 321.82095 | I13: =Calculation!KT4 -> 316.39513 | ... M13: =Calculation!KX4 -> 65.603754 | N13: =SUM(B13:M13) -> 2615.5305
A14: Solar being Exported to Grid without Battery | B14: =Calculation!KM5 -> 5.2371246 | C14: =Calculation!KN5 -> 33.61092 | D14: =Calculation!KO5 -> 82.241484 | E14: =Calculation!KP5 -> 152.39421 | F14: =Calculation!KQ5 -> 216.41439 | G14: =Calculation!KR5 -> 144.89306 | H14: =Calculation!KS5 -> 162.97397 | I14: =Calculation!KT5 -> 168.87911 | ... M14: =Calculation!KX5 -> 2.3820235 | N14: =SUM(B14:M14) -> 1148.3488
A15: Solar Being Used by Home without Battery | B15: =Calculation!KM6 -> 69.318073 | C15: =Calculation!KN6 -> 105.36251 | D15: =Calculation!KO6 -> 142.10027 | E15: =Calculation!KP6 -> 155.556 | F15: =Calculation!KQ6 -> 167.40832 | G15: =Calculation!KR6 -> 156.41865 | H15: =Calculation!KS6 -> 158.84698 | I15: =Calculation!KT6 -> 147.51602 | ... M15: =Calculation!KX6 -> 63.221731 | N15: =SUM(B15:M15) -> 1467.1817
A16: Grid Usage After Solar | B16: =Calculation!KM7 -> 335.66337 | C16: =Calculation!KN7 -> 248.7605 | D16: =Calculation!KO7 -> 218.86326 | E16: =Calculation!KP7 -> 156.35145 | F16: =Calculation!KQ7 -> 132.27011 | G16: =Calculation!KR7 -> 119.89592 | H16: =Calculation!KS7 -> 123.1131 | I16: =Calculation!KT7 -> 139.27432 | ... M16: =Calculation!KX7 -> 350.46474 | N16: =SUM(B16:M16) -> 2532.8183
A17: Solar Being Exported to Grid With Battery | B17: =Calculation!KM8 -> 5.231661 | C17: =Calculation!KN8 -> 33.53692 | D17: =Calculation!KO8 -> 76.317209 | E17: =Calculation!KP8 -> 100.92404 | F17: =Calculation!KQ8 -> 92.043291 | G17: =Calculation!KR8 -> 80.989327 | H17: =Calculation!KS8 -> 82.371866 | I17: =Calculation!KT8 -> 93.981604 | ... M17: =Calculation!KX8 -> 2.3805183 | N17: =SUM(B17:M17) -> 720.45974
A18: Solar Being Used by Home with Battery | B18: =Calculation!KM9 -> 74.549734 | C18: =Calculation!KN9 -> 138.89943 | D18: =Calculation!KO9 -> 218.41747 | E18: =Calculation!KP9 -> 256.48003 | F18: =Calculation!KQ9 -> 259.45161 | G18: =Calculation!KR9 -> 237.40798 | H18: =Calculation!KS9 -> 241.21885 | I18: =Calculation!KT9 -> 241.49762 | ... M18: =Calculation!KX9 -> 65.602249 | N18: =SUM(B18:M18) -> 2187.6414
A19: Grid Usage After Solar and Battery | B19: =Calculation!KM10 -> 330.43171 | C19: =Calculation!KN10 -> 215.22358 | D19: =Calculation!KO10 -> 142.54605 | E19: =Calculation!KP10 -> 55.427416 | F19: =Calculation!KQ10 -> 40.226824 | G19: =Calculation!KR10 -> 38.906592 | H19: =Calculation!KS10 -> 40.741237 | I19: =Calculation!KT10 -> 45.29272 | ... M19: =Calculation!KX10 -> 348.08423 | N19: =SUM(B19:M19) -> 1812.3586
A20: YOUR PREDICTED SYSTEM PERFORMANCE
A21: The Assumptions we have made are based on… | F21: Environmental Impact… | J21: Address and Climate Data…
A22: Predicted System Output | B22: Shading Factor | C22: Assumed Annual Inflation as per UK RPI forecast | D22: Assumed On-Site Energy Consumption | F22: CO² Savings | J22: Project Reference | L22: Postcode | M22: Irradience Zone | N22: Roof Pitch
A23: ='Usage and Savings'!B7 -> 2615.5305 kWh/annum | B23: =Input!D14 -> 0.95 | C23: ='Usage and Savings'!C7 -> 0.03 | D23: =Calculation!KZ9 -> 0.83640449 | F23: ='Usage and Savings'!E7 -> 0.517kg saved per PV kWh | J23: ='Usage and Savings'!F7 -> 44293 | L23: ='Usage and Savings'!G7 | M23: ='Usage and Savings'!H7 -> 3 | N23: ='Usage and Savings'!I7 -> 35⁰
A24: Our Proposal Installation Cost | C24: Assumed Energy Unit Cost | D24: Assumed Annual Energy Inflation, iline with the office off national satistics 2005/2019 | F24: CO² Savings Over 20 Years | J24: Address | L24: ='Usage and Savings'!G8 -> Export Rate | M24: Irradiation Level | N24: Degree's From South
A25: =A2 -> 6271.0814 | C25: ='Usage and Savings'!C9 -> 0.17556 | D25: ='Usage and Savings'!D9 -> 0.07 | F25: ='Usage and Savings'!E9 -> 25.76 tonnes | J25: ='Usage and Savings'!F9 -> , , | L25: ='Usage and Savings'!G9 -> 0.055 | M25: ='Usage and Savings'!H9 -> 927 | N25: ='Usage and Savings'!I9 -> 30⁰
A26: YOUR PREDICTED SYSTEM PERFORMANCE 20 YEAR OUTLOOK
A27: Year | B27: Estimated Yearly Energy (kWh) | C27: Predicted Unit Cost Plus Inflation | D27: Current energy bills | F27: Estimated Generation (kWh) Of Solar System | G27: Collector Efficiency of Solar System | H27: Electricity Used on Site (kWh) from Solar & Storage | I27: Solar Savings/Benefit | K27: Predicted Energy Bills after Solar Installed | M27: Solar Savings/Benefit accumulative Total
A28: 1 | B28: ='Usage and Savings'!C13 -> 4000 kWh | C28: ='Usage and Savings'!D13 -> 0.17556 | D28: ='Usage and Savings'!E13 -> 783.489 | F28: ='Usage and Savings'!F13 -> 2615.5305 | G28: ='Usage and Savings'!G13 -> 1 | H28: ='Usage and Savings'!H13 -> 2187.6414 | I28: ='Usage and Savings'!I13+'Usage and Savings'!L13 -> 407.59623 | K28: ='Usage and Savings'!M13 -> 399.42667 | M28: ='Usage and Savings'!O13 -> 407.59623
A29: 2 | B29: ='Usage and Savings'!C14 -> 4000 kWh | C29: ='Usage and Savings'!D14 -> 0.1878492 | D29: ='Usage and Savings'!E14 -> 832.6458 | F29: ='Usage and Savings'!F14 -> 2602.4528 | G29: ='Usage and Savings'!G14 -> 0.995 | H29: ='Usage and Savings'!H14 -> 2187.6414 | I29: ='Usage and Savings'!I14+'Usage and Savings'!L14 -> 434.44576 | K29: ='Usage and Savings'!M14 -> 421.6991 | M29: ='Usage and Savings'!O14 -> 842.04199
A30: 3 | B30: ='Usage and Savings'!C15 -> 4000 kWh | C30: ='Usage and Savings'!D15 -> 0.20099864 | D30: ='Usage and Savings'!E15 -> 885.24358 | F30: ='Usage and Savings'!F15 -> 2589.3752 | G30: ='Usage and Savings'!G15 -> 0.99 | H30: ='Usage and Savings'!H15 -> 2187.6414 | I30: ='Usage and Savings'!I15+'Usage and Savings'!L15 -> 463.15393 | K30: ='Usage and Savings'!M15 -> 445.53061 | M30: ='Usage and Savings'!O15 -> 1305.1959
A31: 4 | B31: ='Usage and Savings'!C16 -> 4000 kWh | C31: ='Usage and Savings'!D16 -> 0.21506855 | D31: ='Usage and Savings'!E16 -> 941.5232 | F31: ='Usage and Savings'!F16 -> 2576.2975 | G31: ='Usage and Savings'!G16 -> 0.985 | H31: ='Usage and Savings'!H16 -> 2187.6414 | I31: ='Usage and Savings'!I16+'Usage and Savings'!L16 -> 493.8511 | K31: ='Usage and Savings'!M16 -> 471.03033 | M31: ='Usage and Savings'!O16 -> 1799.047
A32: 5 | B32: ='Usage and Savings'!C17 -> 4000 kWh | C32: ='Usage and Savings'!D17 -> 0.23012335 | D32: ='Usage and Savings'!E17 -> 1001.7424 | F32: ='Usage and Savings'!F17 -> 2563.2199 | G32: ='Usage and Savings'!G17 -> 0.98 | H32: ='Usage and Savings'!H17 -> 2187.6414 | I32: ='Usage and Savings'!I17+'Usage and Savings'!L17 -> 526.6768 | K32: ='Usage and Savings'!M17 -> 498.31502 | M32: ='Usage and Savings'!O17 -> 2325.7238
A33: 6 | B33: ='Usage and Savings'!C18 -> 4000 kWh | C33: ='Usage and Savings'!D18 -> 0.24623198 | D33: ='Usage and Savings'!E18 -> 1066.1769 | F33: ='Usage and Savings'!F18 -> 2550.1422 | G33: ='Usage and Savings'!G18 -> 0.975 | H33: ='Usage and Savings'!H18 -> 2187.6414 | I33: ='Usage and Savings'!I18+'Usage and Savings'!L18 -> 561.78037 | K33: ='Usage and Savings'!M18 -> 527.50964 | M33: ='Usage and Savings'!O18 -> 2887.5042
A34: 7 | B34: ='Usage and Savings'!C19 -> 4000 kWh | C34: ='Usage and Savings'!D19 -> 0.26346822 | D34: ='Usage and Savings'!E19 -> 1135.1219 | F34: ='Usage and Savings'!F19 -> 2537.0646 | G34: ='Usage and Savings'!G19 -> 0.97 | H34: ='Usage and Savings'!H19 -> 2187.6414 | I34: ='Usage and Savings'!I19+'Usage and Savings'!L19 -> 599.32162 | K34: ='Usage and Savings'!M19 -> 558.74788 | M34: ='Usage and Savings'!O19 -> 3486.8258
A35: 8 | B35: ='Usage and Savings'!C20 -> 4000 kWh | C35: ='Usage and Savings'!D20 -> 0.281911 | D35: ='Usage and Savings'!E20 -> 1208.893 | F35: ='Usage and Savings'!F20 -> 2523.9869 | G35: ='Usage and Savings'!G20 -> 0.965 | H35: ='Usage and Savings'!H20 -> 2187.6414 | I35: ='Usage and Savings'!I20+'Usage and Savings'!L20 -> 639.47162 | K35: ='Usage and Savings'!M20 -> 592.17281 | M35: ='Usage and Savings'!O20 -> 4126.2974
A36: 9 | B36: ='Usage and Savings'!C21 -> 4000 kWh | C36: ='Usage and Savings'!D21 -> 0.30164477 | D36: ='Usage and Savings'!E21 -> 1287.8281 | F36: ='Usage and Savings'!F21 -> 2510.9093 | G36: ='Usage and Savings'!G21 -> 0.96 | H36: ='Usage and Savings'!H21 -> 2187.6414 | I36: ='Usage and Savings'!I21+'Usage and Savings'!L21 -> 682.41342 | K36: ='Usage and Savings'!M21 -> 627.93747 | M36: ='Usage and Savings'!O21 -> 4808.7108
A37: 10 | B37: ='Usage and Savings'!C22 -> 4000 kWh | C37: ='Usage and Savings'!D22 -> 0.3227599 | D37: ='Usage and Savings'!E22 -> 1372.2886 | F37: ='Usage and Savings'!F22 -> 2497.8316 | G37: ='Usage and Savings'!G22 -> 0.955 | H37: ='Usage and Savings'!H22 -> 2187.6414 | I37: ='Usage and Savings'!I22+'Usage and Savings'!L22 -> 728.34296 | K37: ='Usage and Savings'!M22 -> 666.20566 | M37: ='Usage and Savings'!O22 -> 5537.0538
A38: Total Energy Spend/Loss at 10 Years | D38: =SUM(D28:E37) -> 10514.952 | F38: Total 10 year Savings/Benefit | I38: =SUM(I28:I37) -> 5537.0538
A39: 11 | B39: ='Usage and Savings'!C23 -> 4000 kWh | C39: ='Usage and Savings'!D23 -> 0.34535309 | D39: ='Usage and Savings'!E23 -> 1462.6614 | F39: ='Usage and Savings'!F23 -> 2484.754 | G39: ='Usage and Savings'!G23 -> 0.95 | H39: ='Usage and Savings'!H23 -> 2187.6414 | I39: ='Usage and Savings'!I23+'Usage and Savings'!L23 -> 777.46993 | K39: ='Usage and Savings'!M23 -> 707.15263 | M39: ='Usage and Savings'!O23 -> 6314.5237
A40: 12 | B40: ='Usage and Savings'!C24 -> 4000 kWh | C40: ='Usage and Savings'!D24 -> 0.36952781 | D40: ='Usage and Savings'!E24 -> 1559.3602 | F40: ='Usage and Savings'!F24 -> 2471.6763 | G40: ='Usage and Savings'!G24 -> 0.945 | H40: ='Usage and Savings'!H24 -> 2187.6414 | I40: ='Usage and Savings'!I24+'Usage and Savings'!L24 -> 830.01874 | K40: ='Usage and Savings'!M24 -> 750.96589 | M40: ='Usage and Savings'!O24 -> 7144.5425
A41: 13 | B41: ='Usage and Savings'!C25 -> 4000 kWh | C41: ='Usage and Savings'!D25 -> 0.39539476 | D41: ='Usage and Savings'!E25 -> 1662.828 | F41: ='Usage and Savings'!F25 -> 2458.5987 | G41: ='Usage and Savings'!G25 -> 0.94 | H41: ='Usage and Savings'!H25 -> 2187.6414 | I41: ='Usage and Savings'!I25+'Usage and Savings'!L25 -> 886.22957 | K41: ='Usage and Savings'!M25 -> 797.84607 | M41: ='Usage and Savings'!O25 -> 8030.772
...

Sheet Costing
A1: Solar kW dc | C1: =Input!D12 -> 2.97 | D1: Roof Type | E1: =Input!D19 -> Concrete | F1: Scaffold Required | G1: =Input!D21 -> No | H1: Battery Size | I1: =Input!D22 -> 5 | J1: Margin | K1: =Input!D34 -> 0.5 | L1: VAT | M1: =Input!D35 -> 0.05 | N1: Discount | O1: =Input!D33 -> 0.5
B2: Panel Quantity | C2: =Input!D9 -> 9 | D2: Panel Type | E2: =Input!D20 -> Black | M2: =H27/($C$1*1000) -> 1.8747335
A3: DO NOT EDIT THIS SECTION | B3: Description | C3: Type | D3: Cost Per KW | E3: Cost | F3: Cost Applied | G3: Margin | H3: Total Sale | I3: Pence Per W | J3: VAT | K3: Total Sale Inc VAT | M3: =K27/($C$1*1000) -> 1.9684702
B4: Concrete Roof | C4: Concrete | D4: 75.59 | E4: =D4*$C$1 -> 224.5023 | F4: =SUMIFS(E4,C4,$E$1) -> 224.5023 | G4: =F4*$K$1 -> 112.25115 | H4: =SUM(F4:G4) -> 336.75345 | I4: =H4/($C$1*1000) -> 0.113385 | J4: =H4*$M$1 -> 16.837673 | K4: =J4+H4 -> 353.59112 | M4: =F27/($C$1*1000) -> 1.2498223
B5: Slate Roof | C5: Slate | D5: 90.59 | E5: =D5*$C$1 -> 269.0523 | F5: =SUMIFS(E5,C5,$E$1) -> 0 | G5: =F5*$K$1 -> 0 | H5: =SUM(F5:G5) -> 0 | I5: =H5/($C$1*1000) -> 0 | J5: =H5*$M$1 -> 0 | K5: =J5+H5 -> 0
B6: Rosemary Roof | C6: Rosemary | D6: 90.59 | E6: =D6*$C$1 -> 269.0523 | F6: =SUMIFS(E6,C6,$E$1) -> 0 | G6: =F6*$K$1 -> 0 | H6: =SUM(F6:G6) -> 0 | I6: =H6/($C$1*1000) -> 0 | J6: =H6*$M$1 -> 0 | K6: =J6+H6 -> 0
B7: Flat Roof | C7: Flat Roof | D7: 125 | E7: =D7*$C$1 -> 371.25 | F7: =SUMIFS(E7,C7,$E$1) -> 0 | G7: =F7*$K$1 -> 0 | H7: =SUM(F7:G7) -> 0 | I7: =H7/($C$1*1000) -> 0 | J7: =H7*$M$1 -> 0 | K7: =J7+H7 -> 0
B8: Ground Mounted | C8: Ground Mounted | D8: 130 | E8: =D8*$C$1 -> 386.1 | F8: =SUMIFS(E8,C8,$E$1) -> 0 | G8: =F8*$K$1 -> 0 | H8: =SUM(F8:G8) -> 0 | I8: =H8/($C$1*1000) -> 0 | J8: =H8*$M$1 -> 0 | K8: =J8+H8 -> 0
B9: In Roof | C9: In Roof | D9: 60 | E9: =D9*C2 -> 540 | F9: =SUMIFS(E9,C9,$E$1) -> 0 | G9: =F9*$K$1 -> 0 | H9: =SUM(F9:G9) -> 0 | I9: =H9/($C$1*1000) -> 0 | J9: =H9*$M$1 -> 0 | K9: =J9+H9 -> 0
B10: Dekra Roof | C10: Dekra | D10: 80.59 | E10: =D10*$C$1 -> 239.3523 | F10: =SUMIFS(E10,C10,$E$1) -> 0 | G10: =F10*$K$1 -> 0 | H10: =SUM(F10:G10) -> 0 | I10: =H10/($C$1*1000) -> 0 | J10: =H10*$M$1 -> 0 | K10: =J10+H10 -> 0
B11: Ancillary Materials | C11: Per KW | D11: 40 | E11: =D11*$C$1 -> 118.8 | F11: =E11 -> 118.8 | G11: =F11*$K$1 -> 59.4 | H11: =SUM(F11:G11) -> 178.2 | I11: =H11/($C$1*1000) -> 0.06 | J11: =H11*$M$1 -> 8.91 | K11: =J11+H11 -> 187.11 | M11: Module Cost
B12: Solar Modules Blue | C12: Blue | D12: 210 | E12: =D12*$C$1 -> 623.7 | F12: =SUMIFS(E12,C12,$E$2) -> 0 | G12: =F12*$K$1 -> 0 | H12: =SUM(F12:G12) -> 0 | I12: =H12/($C$1*1000) -> 0 | J12: =H12*$M$1 -> 0 | K12: =J12+H12 -> 0 | M12: =E12/C$2 -> 69.3
B13: Solar Modules Black | C13: Black | D13: 240 | E13: =D13*$C$1 -> 712.8 | F13: =SUMIFS(E13,C13,$E$2) -> 712.8 | G13: =F13*$K$1 -> 356.4 | H13: =SUM(F13:G13) -> 1069.2 | I13: =H13/($C$1*1000) -> 0.36 | J13: =H13*$M$1 -> 53.46 | K13: =J13+H13 -> 1122.66 | M13: =E13/C$2 -> 79.2
B14: Inverter | C14: Per KW | D14: 92 | E14: =D14*$C$1 -> 273.24 | F14: =E14 -> 273.24 | G14: =F14*$K$1 -> 136.62 | H14: =SUM(F14:G14) -> 409.86 | I14: =H14/($C$1*1000) -> 0.138 | J14: =H14*$M$1 -> 20.493 | K14: =J14+H14 -> 430.353
B15: Metering Equipment | C15: Per Job | D15: N/A | E15: 120.5 | F15: =E15 -> 120.5 | G15: =F15*$K$1 -> 60.25 | H15: =SUM(F15:G15) -> 180.75 | I15: =H15/($C$1*1000) -> 0.060858586 | J15: =H15*$M$1 -> 9.0375 | K15: =J15+H15 -> 189.7875
B16: Battery Equipment 3KW | C16: 2.5 | D16: N/A | E16: =480+370 -> 850 | F16: =SUMIFS(E16,C16,$I$1) -> 0 | G16: =F16*$K$1 -> 0 | H16: =SUM(F16:G16) -> 0 | I16: =H16/($C$1*1000) -> 0 | J16: =H16*$M$1 -> 0 | K16: =J16+H16 -> 0
B17: Battery Equipment 5KW | C17: 5 | D17: N/A | E17: =960+370 -> 1330 | F17: =SUMIFS(E17,C17,$I$1) -> 1330 | G17: =F17*$K$1 -> 665 | H17: =SUM(F17:G17) -> 1995 | I17: =H17/($C$1*1000) -> 0.67171717 | J17: =H17*$M$1 -> 99.75 | K17: =J17+H17 -> 2094.75
B18: Battery Equipment 7.5KW | C18: 7.5 | D18: N/A | E18: =1480+370 -> 1850 | F18: =SUMIFS(E18,C18,$I$1) -> 0 | G18: =F18*$K$1 -> 0 | H18: =SUM(F18:G18) -> 0 | I18: =H18/($C$1*1000) -> 0 | J18: =H18*$M$1 -> 0 | K18: =J18+H18 -> 0
B19: Battery Equipment 10KW | C19: 10 | D19: N/A | E19: =1960+370 -> 2330 | F19: =SUMIFS(E19,C19,$I$1) -> 0 | G19: =F19*$K$1 -> 0 | H19: =SUM(F19:G19) -> 0 | I19: =H19/($C$1*1000) -> 0 | J19: =H19*$M$1 -> 0 | K19: =J19+H19 -> 0
B20: Labour | C20: Per KW | D20: 160 | E20: =D20*$C$1 -> 475.2 | F20: =E20 -> 475.2 | G20: =F20*$K$1 -> 237.6 | H20: =SUM(F20:G20) -> 712.8 | I20: =H20/($C$1*1000) -> 0.24 | J20: =H20*$M$1 -> 35.64 | K20: =J20+H20 -> 748.44
B21: Scaffold | C21: Per Job | D21: N/A | E21: 500 | F21: =SUMIFS(E21,G1,"Yes") -> 0 | G21: =F21*$K$1 -> 0 | H21: =SUM(F21:G21) -> 0 | I21: =H21/($C$1*1000) -> 0 | J21: =H21*$M$1 -> 0 | K21: =J21+H21 -> 0
B22: H&S and Project Management | C22: Per Job | D22: N/A | E22: 0 | F22: =E22 -> 0 | G22: =F22*$K$1 -> 0 | H22: =SUM(F22:G22) -> 0 | I22: =H22/($C$1*1000) -> 0 | J22: =H22*$M$1 -> 0 | K22: =(J22+H22) -> 0
B23: Commissioning | C23: Per Job | D23: N/A | E23: 0 | F23: =E23 -> 0 | G23: =F23*$K$1 -> 0 | H23: =SUM(F23:G23) -> 0 | I23: =H23/($C$1*1000) -> 0 | J23: =H23*$M$1 -> 0 | K23: =(J23+H23) -> 0
B24: Packaging and Delivery | C24: Per Job | D24: N/A | E24: =150 -> 150 | F24: =E24 -> 150 | G24: =F24*$K$1 -> 75 | H24: =SUM(F24:G24) -> 225 | I24: =H24/($C$1*1000) -> 0.075757576 | J24: =H24*$M$1 -> 11.25 | K24: =(J24+H24) -> 236.25
B25: Administration / Lead Fees | C25: Per Job | D25: N/A | E25: 137.93 | F25: =E25 -> 137.93 | G25: =F25*$K$1 -> 68.965 | H25: =SUM(F25:G25) -> 206.895 | I25: =H25/($C$1*1000) -> 0.069661616 | J25: =H25*$M$1 -> 10.34475 | K25: =(J25+H25) -> 217.23975
B26: Registrations | C26: Per Job | D26: N/A | E26: =35+89+45 -> 169 | F26: =E26 -> 169 | G26: =F26*$K$1 -> 84.5 | H26: =SUM(F26:G26) -> 253.5 | I26: =H26/($C$1*1000) -> 0.085353535 | J26: =H26*$M$1 -> 12.675 | K26: =(J26+H26) -> 266.175
F27: =SUM(F4:F26) -> 3711.9723 | G27: =SUM(G4:G26) -> 1855.9861 | H27: =SUM(H4:H26) -> 5567.9585 | I27: =H27/($C$1*1000) -> 1.8747335 | J27: =SUM(J4:J26) -> 278.39792 | K27: =SUM(K4:K26) -> 5846.3564
A29: ADD UPLIFT AND ADDITIONAL ITEMS IN YELLOW ONLY | B29: Additional Items | C29: Type | E29: Cost | G29: Margin | H29: Total Sale | I29: VAT Rate | K29: VAT | L29: Total Sale Inc VAT
B30: =Input!D36 -> Solar Edge | C30: =VLOOKUP(B30,'Lookup Data'!A:B,2,0) -> Addition | E30: =VLOOKUP(B30,'Lookup Data'!A:C,3,0) -> 270 | G30: =E30*$K$1 -> 135 | H30: =G30+E30 -> 405 | I30: =VLOOKUP(B30,'Lookup Data'!A:D,4,0) -> 0.05 | K30: =H30*I30 -> 20.25 | L30: =K30+H30 -> 425.25
B31: =Input!D37 -> None | C31: =VLOOKUP(B31,'Lookup Data'!A:B,2,0) -> None | E31: =VLOOKUP(B31,'Lookup Data'!A:C,3,0) -> 0 | G31: =E31*$K$1 -> 0 | H31: =G31+E31 -> 0 | I31: =VLOOKUP(B31,'Lookup Data'!A:D,4,0) -> 0 | K31: =H31*I31 -> 0 | L31: =K31+H31 -> 0
B32: =Input!D38 -> None | C32: =VLOOKUP(B32,'Lookup Data'!A:B,2,0) -> None | E32: =VLOOKUP(B32,'Lookup Data'!A:C,3,0) -> 0 | G32: =E32*$K$1 -> 0 | H32: =G32+E32 -> 0 | I32: =VLOOKUP(B32,'Lookup Data'!A:D,4,0) -> 0 | K32: =H32*I32 -> 0 | L32: =K32+H32 -> 0
B33: =Input!D39 -> None | C33: =VLOOKUP(B33,'Lookup Data'!A:B,2,0) -> None | E33: =VLOOKUP(B33,'Lookup Data'!A:C,3,0) -> 0 | G33: =E33*$K$1 -> 0 | H33: =G33+E33 -> 0 | I33: =VLOOKUP(B33,'Lookup Data'!A:D,4,0) -> 0 | K33: =H33*I33 -> 0 | L33: =K33+H33 -> 0
E34: =SUM(E30:E33) -> 270 | G34: =SUM(G30:G33) -> 135 | H34: =SUM(H30:H33) -> 405 | I34: 0 | K34: =SUM(K30:K33) -> 20.25 | L34: =K34+H34 -> 425.25
E35: Total Cost | G35: Total Margin | H35: Total Sale | K35: Total VAT | L35: Total Sale Inc VAT
E36: Places for People Fee | H36: =-Input!D33 -> -0.5
E37: =F27+F34 -> 3711.9723 | G37: =G27+G34-G36 -> 1990.9861 | H37: =H27+H34+H36 -> 5972.4585 | K37: =H37*5% -> 298.62292 | L37: =K37+H37 -> 6271.0814

Sheet Usage and Savings
B2: Predicted System Performance
B4: The Assumptions we have made are based on… | E4: Environmental Impact… | F4: Address and Climate Data…
B6: Predicted System Output | C6: Assumed Annual Inflation (RPI) | D6: Assumed On-Site Energy Consumption | E6: CO² Savings | F6: Project Reference | G6: Postcode | H6: Irradience Zone | I6: Roof Pitch
B7: =Input!D15&" "&"kWh/annum" -> 2615.5305 kWh/annum | C7: 0.03 | D7: =H13 -> 2187.6414 | E7: 0.517kg saved per PV kWh | F7: =Input!D3 -> 44293 | G7: =Input!D30 | H7: =Input!D16 -> 3 | I7: =Input!D17&Input!C17 -> 35⁰
B8: Our Proposal Installation Cost | C8: Assumed Energy Unit Cost | D8: Assumed Annual Energy Inflation | E8: CO² Savings Over 20 Years | F8: Address | G8: Export Rate | H8: Irradiation Level | I8: Degrees From South
B9: ="£"&(ROUNDUP('Online Sales Pack'!A64,2))&" Inc VAT" -> £6271.09 Inc VAT | C9: =Input!D6 -> 0.17556 | D9: 0.07 | E9: =(ROUND(((SUM(F13:F32)*0.517)/1000),2)&" tonnes") -> 25.76 tonnes | F9: =Input!D27&Input!E25&Input!D28&", "&Input!D29&", "&Input!D30 -> , , | G9: 0.055 | H9: =Input!D13 -> 927 | I9: =Input!D18&Input!C18 -> 30⁰
B11: Your predicted system performance 20 year outlook
B12: Year | C12: Estimated Yearly Energy (kWh) | D12: Predicted Unit Cost Plus Inflation | E12: Predicted Annual Bills before Installation of Solar and Storage | F12: Estimated Generation (kWh) Of Solar System | G12: Collector Efficiency of Solar System | H12: Electricity Used on Site (kWh) from Solar & Storage | I12: Saving from Energy Used From Solar Consumed following Solar & Storage | J12: Exported Power (kWh) | K12: Exported Revenue Rate Per Year | L12: Revenue from Exported Power | M12: Predicted Annual Bills After Installation of Solar | N12: Savings Savings from Solar and Storage System | O12: Accumulative Total | Q12: =COUNTIF(N13:N32,"<0.00001") -> 10
B13: 1 | C13: =Input!D5&" kWh" -> 4000 kWh | D13: =Input!D6 -> 0.17556 | E13: =(D13*Input!$D$5)+(365*Input!$D$7) -> 783.489 | F13: =Input!$D$15*G13 -> 2615.5305 | G13: 1 | H13: =Calculation!$KY$9 -> 2187.6414 | I13: =H13*D13 -> 384.06233 | J13: =F13-H13 -> 427.88906 | K13: =G9 -> 0.055 | L13: =J13*$K13 -> 23.533898 | M13: =E13-I13 -> 399.42667 | N13: =-Costing!L37+I13+L13 -> -5863.4851 | O13: =I13+L13 -> 407.59623
B14: 2 | C14: =C13 -> 4000 kWh | D14: =(D13+(D13*$D$9)) -> 0.1878492 | E14: =(D14*Input!$D$5)+(365*Input!$D$7) -> 832.6458 | F14: =Input!$D$15*G14 -> 2602.4528 | G14: =G13-0.005 -> 0.995 | H14: =Calculation!$KY$9 -> 2187.6414 | I14: =H14*D14 -> 410.9467 | J14: =F14-H14 -> 414.8114 | K14: =(K13+(K13*$C$7)) -> 0.05665 | L14: =J14*$K14 -> 23.499066 | M14: =E14-I14 -> 421.6991 | N14: =N13+I14+L14 -> -5429.0394 | O14: =O13+I14+L14 -> 842.04199
B15: 3 | C15: =C14 -> 4000 kWh | D15: =(D14+(D14*$D$9)) -> 0.20099864 | E15: =(D15*Input!$D$5)+(365*Input!$D$7) -> 885.24358 | F15: =Input!$D$15*G15 -> 2589.3752 | G15: =G14-0.005 -> 0.99 | H15: =Calculation!$KY$9 -> 2187.6414 | I15: =H15*D15 -> 439.71296 | J15: =F15-H15 -> 401.73375 | K15: =(K14+(K14*$C$7)) -> 0.0583495 | L15: =J15*$K15 -> 23.440963 | M15: =E15-I15 -> 445.53061 | N15: =N14+I15+L15 -> -4965.8855 | O15: =O14+I15+L15 -> 1305.1959
B16: 4 | C16: =C15 -> 4000 kWh | D16: =(D15+(D15*$D$9)) -> 0.21506855 | E16: =(D16*Input!$D$5)+(365*Input!$D$7) -> 941.5232 | F16: =Input!$D$15*G16 -> 2576.2975 | G16: =G15-0.005 -> 0.985 | H16: =Calculation!$KY$9 -> 2187.6414 | I16: =H16*D16 -> 470.49287 | J16: =F16-H16 -> 388.6561 | K16: =(K15+(K15*$C$7)) -> 0.060099985 | L16: =J16*$K16 -> 23.358226 | M16: =E16-I16 -> 471.03033 | N16: =N15+I16+L16 -> -4472.0344 | O16: =O15+I16+L16 -> 1799.047
B17: 5 | C17: =C16 -> 4000 kWh | D17: =(D16+(D16*$D$9)) -> 0.23012335 | E17: =(D17*Input!$D$5)+(365*Input!$D$7) -> 1001.7424 | F17: =Input!$D$15*G17 -> 2563.2199 | G17: =G16-0.005 -> 0.98 | H17: =Calculation!$KY$9 -> 2187.6414 | I17: =H17*D17 -> 503.42737 | J17: =F17-H17 -> 375.57845 | K17: =(K16+(K16*$C$7)) -> 0.061902985 | L17: =J17*$K17 -> 23.249427 | M17: =E17-I17 -> 498.31502 | N17: =N16+I17+L17 -> -3945.3576 | O17: =O16+I17+L17 -> 2325.7238
B18: 6 | C18: =C17 -> 4000 kWh | D18: =(D17+(D17*$D$9)) -> 0.24623198 | E18: =(D18*Input!$D$5)+(365*Input!$D$7) -> 1066.1769 | F18: =Input!$D$15*G18 -> 2550.1422 | G18: =G17-0.005 -> 0.975 | H18: =Calculation!$KY$9 -> 2187.6414 | I18: =H18*D18 -> 538.66729 | J18: =F18-H18 -> 362.50079 | K18: =(K17+(K17*$C$7)) -> 0.063760074 | L18: =J18*$K18 -> 23.113077 | M18: =E18-I18 -> 527.50964 | N18: =N17+I18+L18 -> -3383.5772 | O18: =O17+I18+L18 -> 2887.5042
B19: 7 | C19: =C18 -> 4000 kWh | D19: =(D18+(D18*$D$9)) -> 0.26346822 | E19: =(D19*Input!$D$5)+(365*Input!$D$7) -> 1135.1219 | F19: =Input!$D$15*G19 -> 2537.0646 | G19: =G18-0.005 -> 0.97 | H19: =Calculation!$KY$9 -> 2187.6414 | I19: =H19*D19 -> 576.374 | J19: =F19-H19 -> 349.42314 | K19: =(K18+(K18*$C$7)) -> 0.065672876 | L19: =J19*$K19 -> 22.947623 | M19: =E19-I19 -> 558.74788 | N19: =N18+I19+L19 -> -2784.2556 | O19: =O18+I19+L19 -> 3486.8258
B20: 8 | C20: =C19 -> 4000 kWh | D20: =(D19+(D19*$D$9)) -> 0.281911 | E20: =(D20*Input!$D$5)+(365*Input!$D$7) -> 1208.893 | F20: =Input!$D$15*G20 -> 2523.9869 | G20: =G19-0.005 -> 0.965 | H20: =Calculation!$KY$9 -> 2187.6414 | I20: =H20*D20 -> 616.72018 | J20: =F20-H20 -> 336.34549 | K20: =(K19+(K19*$C$7)) -> 0.067643063 | L20: =J20*$K20 -> 22.751439 | M20: =E20-I20 -> 592.17281 | N20: =N19+I20+L20 -> -2144.784 | O20: =O19+I20+L20 -> 4126.2974
B21: 9 | C21: =C20 -> 4000 kWh | D21: =(D20+(D20*$D$9)) -> 0.30164477 | E21: =(D21*Input!$D$5)+(365*Input!$D$7) -> 1287.8281 | F21: =Input!$D$15*G21 -> 2510.9093 | G21: =G20-0.005 -> 0.96 | H21: =Calculation!$KY$9 -> 2187.6414 | I21: =H21*D21 -> 659.89059 | J21: =F21-H21 -> 323.26784 | K21: =(K20+(K20*$C$7)) -> 0.069672354 | L21: =J21*$K21 -> 22.522831 | M21: =E21-I21 -> 627.93747 | N21: =N20+I21+L21 -> -1462.3705 | O21: =O20+I21+L21 -> 4808.7108
B22: 10 | C22: =C21 -> 4000 kWh | D22: =(D21+(D21*$D$9)) -> 0.3227599 | E22: =(D22*Input!$D$5)+(365*Input!$D$7) -> 1372.2886 | F22: =Input!$D$15*G22 -> 2497.8316 | G22: =G21-0.005 -> 0.955 | H22: =Calculation!$KY$9 -> 2187.6414 | I22: =H22*D22 -> 706.08293 | J22: =F22-H22 -> 310.19018 | K22: =(K21+(K21*$C$7)) -> 0.071762525 | L22: =J22*$K22 -> 22.260031 | M22: =E22-I22 -> 666.20566 | N22: =N21+I22+L22 -> -734.02757 | O22: =O21+I22+L22 -> 5537.0538
B23: 11 | C23: =C22 -> 4000 kWh | D23: =(D22+(D22*$D$9)) -> 0.34535309 | E23: =(D23*Input!$D$5)+(365*Input!$D$7) -> 1462.6614 | F23: =Input!$D$15*G23 -> 2484.754 | G23: =G22-0.005 -> 0.95 | H23: =Calculation!$KY$9 -> 2187.6414 | I23: =H23*D23 -> 755.50874 | J23: =F23-H23 -> 297.11253 | K23: =(K22+(K22*$C$7)) -> 0.073915401 | L23: =J23*$K23 -> 21.961192 | M23: =E23-I23 -> 707.15263 | N23: =N22+I23+L23 -> 43.442361 | O23: =O22+I23+L23 -> 6314.5237
B24: 12 | C24: =C23 -> 4000 kWh | D24: =(D23+(D23*$D$9)) -> 0.36952781 | E24: =(D24*Input!$D$5)+(365*Input!$D$7) -> 1559.3602 | F24: =Input!$D$15*G24 -> 2471.6763 | G24: =G23-0.005 -> 0.945 | H24: =Calculation!$KY$9 -> 2187.6414 | I24: =H24*D24 -> 808.39435 | J24: =F24-H24 -> 284.03488 | K24: =(K23+(K23*$C$7)) -> 0.076132863 | L24: =J24*$K24 -> 21.624388 | M24: =E24-I24 -> 750.96589 | N24: =N23+I24+L24 -> 873.4611 | O24: =O23+I24+L24 -> 7144.5425
B25: 13 | C25: =C24 -> 4000 kWh | D25: =(D24+(D24*$D$9)) -> 0.39539476 | E25: =(D25*Input!$D$5)+(365*Input!$D$7) -> 1662.828 | F25: =Input!$D$15*G25 -> 2458.5987 | G25: =G24-0.005 -> 0.94 | H25: =Calculation!$KY$9 -> 2187.6414 | I25: =H25*D25 -> 864.98195 | J25: =F25-H25 -> 270.95723 | K25: =(K24+(K24*$C$7)) -> 0.078416849 | L25: =J25*$K25 -> 21.247612 | M25: =E25-I25 -> 797.84607 | N25: =N24+I25+L25 -> 1759.6907 | O25: =O24+I25+L25 -> 8030.772
... B32: 20 | C32: =C31 -> 4000 kWh | D32: =(D31+(D31*$D$9)) -> 0.63491757 | E32: =(D32*Input!$D$5)+(365*Input!$D$7) -> 2620.9193 | F32: =Input!$D$15*G32 -> 2367.0551 | G32: =G31-0.005 -> 0.905 | H32: =Calculation!$KY$9 -> 2187.6414 | I32: =H32*D32 -> 1388.972 | J32: =F32-H32 -> 179.41366 | K32: =(K31+(K31*$C$7)) -> 0.096442833 | L32: =J32*$K32 -> 17.303161 | M32: =E32-I32 -> 1231.9473 | N32: =N31+I32+L32 -> 9903.6152 | O32: =O31+I32+L32 -> 16174.697

Sheet Profile
A1: Date | B1: Day | C1: Half Hour | D1: HH Period | E1: Solar Coefficient | F1: Consumption Coefficient
A2: 43466 | B2: 1 | C2: 1 | D2: 0 | E2: 0 | F2: 6.0793852e-05
A3: 43466 | B3: 1 | C3: 2 | D3: 0.020833333 | E3: 0 | F3: 5.5385503e-05
A4: 43466 | B4: 1 | C4: 3 | D4: 0.041666667 | E4: 0 | F4: 5.2881637e-05
A5: 43466 | B5: 1 | C5: 4 | D5: 0.0625 | E5: 0 | F5: 4.9876999e-05
A6: 43466 | B6: 1 | C6: 5 | D6: 0.083333333 | E6: 0 | F6: 4.9075762e-05
A7: 43466 | B7: 1 | C7: 6 | D7: 0.10416667 | E7: 0 | F7: 4.1764475e-05
A8: 43466 | B8: 1 | C8: 7 | D8: 0.125 | E8: 0 | F8: 3.8960146e-05
A9: 43466 | B9: 1 | C9: 8 | D9: 0.14583333 | E9: 0 | F9: 3.5955507e-05
A10: 43466 | B10: 1 | C10: 9 | D10: 0.16666667 | E10: 0 | F10: 3.4653497e-05
A11: 43466 | B11: 1 | C11: 10 | D11: 0.1875 | E11: 0 | F11: 3.4152724e-05
A12: 43466 | B12: 1 | C12: 11 | D12: 0.20833333 | E12: 0 | F12: 3.4553343e-05
A13: 43466 | B13: 1 | C13: 12 | D13: 0.22916667 | E13: 0 | F13: 3.5054116e-05
... A17521: 43830 | B17521: 365 | C17521: 48 | D17521: 0.97916667 | E17521: 0 | F17521: 5.5685967e-05

Sheet Calculation
KM1: 1 | KN1: 2 | KO1: 3 | KP1: 4 | KQ1: 5 | KR1: 6 | KS1: 7 | KT1: 8 | KU1: 9 | KV1: 10 | KW1: 11 | KX1: 12
KM2: Jan | KN2: Feb | KO2: Mar | KP2: Apr | KQ2: May | KR2: Jun | KS2: Jul | KT2: Aug | KU2: Sep | KV2: Oct | KW2: Nov | KX2: Dec | KY2: Total
KL3: Demand | KM3: =SUMIF($A$11:$A$375,KM$1,$D$11:$D$375) -> 404.98144 | KN3: =SUMIF($A$11:$A$375,KN$1,$D$11:$D$375) -> 354.12301 | KO3: =SUMIF($A$11:$A$375,KO$1,$D$11:$D$375) -> 360.96353 | KP3: =SUMIF($A$11:$A$375,KP$1,$D$11:$D$375) -> 311.90745 | KQ3: =SUMIF($A$11:$A$375,KQ$1,$D$11:$D$375) -> 299.67844 | KR3: =SUMIF($A$11:$A$375,KR$1,$D$11:$D$375) -> 276.31457 | KS3: =SUMIF($A$11:$A$375,KS$1,$D$11:$D$375) -> 281.96008 | KT3: =SUMIF($A$11:$A$375,KT$1,$D$11:$D$375) -> 286.79034 | ... KX3: =SUMIF($A$11:$A$375,KX$1,$D$11:$D$375) -> 413.68648 | KY3: =SUM(KM3:KX3) -> 4000
KL4: Solar | KM4: =SUMIF($A$11:$A$375,KM$1,$BA$11:$BA$375) -> 74.555197 | KN4: =SUMIF($A$11:$A$375,KN$1,$BA$11:$BA$375) -> 138.97343 | KO4: =SUMIF($A$11:$A$375,KO$1,$BA$11:$BA$375) -> 224.34175 | KP4: =SUMIF($A$11:$A$375,KP$1,$BA$11:$BA$375) -> 307.95021 | KQ4: =SUMIF($A$11:$A$375,KQ$1,$BA$11:$BA$375) -> 383.82271 | KR4: =SUMIF($A$11:$A$375,KR$1,$BA$11:$BA$375) -> 301.31171 | KS4: =SUMIF($A$11:$A$375,KS$1,$BA$11:$BA$375) -> 321.82095 | KT4: =SUMIF($A$11:$A$375,KT$1,$BA$11:$BA$375) -> 316.39513 | ... KX4: =SUMIF($A$11:$A$375,KX$1,$BA$11:$BA$375) -> 65.603754 | KY4: =SUM(KM4:KX4) -> 2615.5305
BA5: Total Self Consumption without Battery | CX5: =EU8 -> 1467.1817 | EU5: =CX5/BA8 -> 0.56094995 | KL5: Export | KM5: =SUMIF($A$11:$A$375,KM$1,$CX$11:$CX$375) -> 5.2371246 | KN5: =SUMIF($A$11:$A$375,KN$1,$CX$11:$CX$375) -> 33.61092 | KO5: =SUMIF($A$11:$A$375,KO$1,$CX$11:$CX$375) -> 82.241484 | KP5: =SUMIF($A$11:$A$375,KP$1,$CX$11:$CX$375) -> 152.39421 | KQ5: =SUMIF($A$11:$A$375,KQ$1,$CX$11:$CX$375) -> 216.41439 | KR5: =SUMIF($A$11:$A$375,KR$1,$CX$11:$CX$375) -> 144.89306 | KS5: =SUMIF($A$11:$A$375,KS$1,$CX$11:$CX$375) -> 162.97397 | KT5: =SUMIF($A$11:$A$375,KT$1,$CX$11:$CX$375) -> 168.87911 | ... KX5: =SUMIF($A$11:$A$375,KX$1,$CX$11:$CX$375) -> 2.3820235 | KY5: =SUM(KM5:KX5) -> 1148.3488
B6: Demand (Annual kWh) | C6: =Input!D5 -> 4000 | BA6: Total Self Consumption With Battery | CX6: =CX5+IO8 -> 2187.6414 | EU6: =CX6/BA8 -> 0.83640449 | KL6: Self Consumption Without Battery | KM6: =SUMIF($A$11:$A$375,KM$1,$EU$11:$EU$375) -> 69.318073 | KN6: =SUMIF($A$11:$A$375,KN$1,$EU$11:$EU$375) -> 105.36251 | KO6: =SUMIF($A$11:$A$375,KO$1,$EU$11:$EU$375) -> 142.10027 | KP6: =SUMIF($A$11:$A$375,KP$1,$EU$11:$EU$375) -> 155.556 | KQ6: =SUMIF($A$11:$A$375,KQ$1,$EU$11:$EU$375) -> 167.40832 | KR6: =SUMIF($A$11:$A$375,KR$1,$EU$11:$EU$375) -> 156.41865 | KS6: =SUMIF($A$11:$A$375,KS$1,$EU$11:$EU$375) -> 158.84698 | KT6: =SUMIF($A$11:$A$375,KT$1,$EU$11:$EU$375) -> 147.51602 | ... KX6: =SUMIF($A$11:$A$375,KX$1,$EU$11:$EU$375) -> 63.221731 | KY6: =SUM(KM6:KX6) -> 1467.1817 | KZ6: =KY6/KY4 -> 0.56094995
B7: System Size (kWdc) | C7: =Input!D12 -> 2.97 | BA7: Export After Battery | CX7: =IO8 -> 720.45974 | EU7: =CX7/BA8 -> 0.27545454 | GR7: Battery Size | IO7: =Input!D22 -> 5 | KL7: Demand After Solar | KM7: =SUMIF($A$11:$A$375,KM$1,$GR$11:$GR$375) -> 335.66337 | KN7: =SUMIF($A$11:$A$375,KN$1,$GR$11:$GR$375) -> 248.7605 | KO7: =SUMIF($A$11:$A$375,KO$1,$GR$11:$GR$375) -> 218.86326 | KP7: =SUMIF($A$11:$A$375,KP$1,$GR$11:$GR$375) -> 156.35145 | KQ7: =SUMIF($A$11:$A$375,KQ$1,$GR$11:$GR$375) -> 132.27011 | KR7: =SUMIF($A$11:$A$375,KR$1,$GR$11:$GR$375) -> 119.89592 | KS7: =SUMIF($A$11:$A$375,KS$1,$GR$11:$GR$375) -> 123.1131 | KT7: =SUMIF($A$11:$A$375,KT$1,$GR$11:$GR$375) -> 139.27432 | ... KX7: =SUMIF($A$11:$A$375,KX$1,$GR$11:$GR$375) -> 350.46474 | KY7: =SUM(KM7:KX7) -> 2532.8183
B8: Yield (kWhac Per kWdc) | C8: =Input!D13 -> 927 | D8: =SUM(D11:D375) -> 4000 | E8: 1 | F8: 2 | G8: 3 | H8: 4 | I8: 5 | J8: 6 | K8: 7 | L8: 8 | M8: 9 | N8: 10 | O8: 11 | P8: 12 | Q8: 13 | R8: 14 | S8: 15 | T8: 16 | U8: 17 | V8: 18 | W8: 19 | X8: 20 | Y8: 21 | Z8: 22 | AA8: 23 | AB8: 24 | AC8: 25 | AD8: 26 | AE8: 27 | AF8: 28 | AG8: 29 | AH8: 30 | AI8: 31 | AJ8: 32 | AK8: 33 | AL8: 34 | AM8: 35 | AN8: 36 | AO8: 37 | AP8: 38 | AQ8: 39 | AR8: 40 | AS8: 41 | AT8: 42 | AU8: 43 | AV8: 44 | AW8: 45 | AX8: 46 | AY8: 47 | AZ8: 48 | BA8: =SUM(BA11:BA375) -> 2615.5305 | BB8: 1 | BC8: 2 | BD8: 3 | BE8: 4 | BF8: 5 | BG8: 6 | BH8: 7 | BI8: 8 | BJ8: 9 | BK8: 10 | BL8: 11 | BM8: 12 | BN8: 13 | BO8: 14 | BP8: 15 | BQ8: 16 | BR8: 17 | BS8: 18 | BT8: 19 | BU8: 20 | BV8: 21 | BW8: 22 | BX8: 23 | BY8: 24 | BZ8: 25 | CA8: 26 | CB8: 27 | CC8: 28 | CD8: 29 | CE8: 30 | CF8: 31 | CG8: 32 | CH8: 33 | CI8: 34 | CJ8: 35 | CK8: 36 | CL8: 37 | CM8: 38 | CN8: 39 | CO8: 40 | CP8: 41 | CQ8: 42 | CR8: 43 | CS8: 44 | CT8: 45 | CU8: 46 | CV8: 47 | CW8: 48 | CX8: =SUM(CX11:CX375) -> 1148.3488 | CY8: 1 | CZ8: 2 | DA8: 3 | DB8: 4 | DC8: 5 | DD8: 6 | DE8: 7 | DF8: 8 | DG8: 9 | DH8: 10 | DI8: 11 | DJ8: 12 | DK8: 13 | DL8: 14 | DM8: 15 | DN8: 16 | DO8: 17 | DP8: 18 | DQ8: 19 | DR8: 20 | DS8: 21 | DT8: 22 | DU8: 23 | DV8: 24 | DW8: 25 | DX8: 26 | DY8: 27 | DZ8: 28 | EA8: 29 | EB8: 30 | EC8: 31 | ED8: 32 | EE8: 33 | EF8: 34 | EG8: 35 | EH8: 36 | EI8: 37 | EJ8: 38 | EK8: 39 | EL8: 40 | EM8: 41 | EN8: 42 | EO8: 43 | EP8: 44 | EQ8: 45 | ER8: 46 | ES8: 47 | ET8: 48 | EU8: =SUM(EU11:EU375) -> 1467.1817 | EV8: 1 | EW8: 2 | EX8: 3 | EY8: 4 | EZ8: 5 | FA8: 6 | FB8: 7 | FC8: 8 | FD8: 9 | FE8: 10 | FF8: 11 | FG8: 12 | FH8: 13 | FI8: 14 | FJ8: 15 | FK8: 16 | FL8: 17 | FM8: 18 | FN8: 19 | FO8: 20 | FP8: 21 | FQ8: 22 | FR8: 23 | FS8: 24 | FT8: 25 | FU8: 26 | FV8: 27 | FW8: 28 | FX8: 29 | FY8: 30 | FZ8: 31 | GA8: 32 | GB8: 33 | GC8: 34 | GD8: 35 | GE8: 36 | GF8: 37 | GG8: 38 | GH8: 39 | GI8: 40 | GJ8: 41 | GK8: 42 | GL8: 43 | GM8: 44 | GN8: 45 | GO8: 46 | GP8: 47 | GQ8: 48 | GR8: =SUM(GR11:GR375) -> 2532.8183 | GS8: 1 | GT8: 2 | GU8: 3 | GV8: 4 | GW8: 5 | GX8: 6 | GY8: 7 | GZ8: 8 | HA8: 9 | HB8: 10 | HC8: 11 | HD8: 12 | HE8: 13 | HF8: 14 | HG8: 15 | HH8: 16 | HI8: 17 | HJ8: 18 | HK8: 19 | HL8: 20 | HM8: 21 | HN8: 22 | HO8: 23 | HP8: 24 | HQ8: 25 | HR8: 26 | HS8: 27 | HT8: 28 | HU8: 29 | HV8: 30 | HW8: 31 | HX8: 32 | HY8: 33 | HZ8: 34 | IA8: 35 | IB8: 36 | IC8: 37 | ID8: 38 | IE8: 39 | IF8: 40 | IG8: 41 | IH8: 42 | II8: 43 | IJ8: 44 | IK8: 45 | IL8: 46 | IM8: 47 | IN8: 48 | IO8: =SUM(IO11:IO375) -> 720.45974 | IP8: 1 | IQ8: 2 | IR8: 3 | IS8: 4 | IT8: 5 | IU8: 6 | IV8: 7 | IW8: 8 | IX8: 9 | IY8: 10 | IZ8: 11 | JA8: 12 | JB8: 13 | JC8: 14 | JD8: 15 | JE8: 16 | JF8: 17 | JG8: 18 | JH8: 19 | JI8: 20 | JJ8: 21 | JK8: 22 | JL8: 23 | JM8: 24 | JN8: 25 | JO8: 26 | JP8: 27 | JQ8: 28 | JR8: 29 | JS8: 30 | JT8: 31 | JU8: 32 | JV8: 33 | JW8: 34 | JX8: 35 | JY8: 36 | JZ8: 37 | KA8: 38 | KB8: 39 | KC8: 40 | KD8: 41 | KE8: 42 | KF8: 43 | KG8: 44 | KH8: 45 | KI8: 46 | KJ8: 47 | KK8: 48 | KL8: Export After Battery | KM8: =SUMIF($A$11:$A$375,KM$1,$IO$11:$IO$375) -> 5.231661 | KN8: =SUMIF($A$11:$A$375,KN$1,$IO$11:$IO$375) -> 33.53692 | KO8: =SUMIF($A$11:$A$375,KO$1,$IO$11:$IO$375) -> 76.317209 | KP8: =SUMIF($A$11:$A$375,KP$1,$IO$11:$IO$375) -> 100.92404 | KQ8: =SUMIF($A$11:$A$375,KQ$1,$IO$11:$IO$375) -> 92.043291 | KR8: =SUMIF($A$11:$A$375,KR$1,$IO$11:$IO$375) -> 80.989327 | KS8: =SUMIF($A$11:$A$375,KS$1,$IO$11:$IO$375) -> 82.371866 | KT8: =SUMIF($A$11:$A$375,KT$1,$IO$11:$IO$375) -> 93.981604 | ... KX8: =SUMIF($A$11:$A$375,KX$1,$IO$11:$IO$375) -> 2.3805183 | KY8: =SUM(KM8:KX8) -> 720.45974
