Workbook

Sheet Input
B2: Description | C2: Unit | D2: Value
B3: Project Reference | C3: Unique | D3: =D4&D29 -> 44059
B4: Date | C4: Calculation | D4: =TODAY() -> 44059 | G4: EAC
B5: Electricity Demand | C5: Annual kWh | D5: 100 | F5: Standard Model
B6: Price of Electricity | C6: Per kWh | D6: 100 | F6: Beds | G6: 2 | H6: 3 | I6: 4 | J6: 5 | K6: 6
B7: Standing Charge | C7: Per Day | D7: 100 | F7: Low User | G7: 2000 | H7: 3000 | I7: 4150 | J7: 4500 | K7: 4750
B8: Annual Cost of Electricity | C8: Calculation | D8: =(D5*D6)+(D7*365) -> 0 | F8: Std User | G8: 2500 | H8: 3500 | I8: 4650 | J8: 5000 | K8: 5250
B9: Quantity of Panels | C9: Number | D9: 10 | F9: High User | G9: 3500 | H9: 4500 | I9: 5650 | J9: 6000 | K9: 6250
B10: Panel Manufacturer | C10: Option | D10: Phonosolar (Preferred) | F10: Add Below to above EAC if Required
B11: Panel Wattage | C11: Option | D11: 270 | F11: Electric Car | G11: 2500
B12: System Size | C12: Calculated kW dc | D12: =(D9*D11)/1000 -> 2.7 | F12: Air Source Heating | G12: 3000
B13: Specific Yield | C13: Annual kWh per KW | F13: Swimming Pool (Electric) | G13: 3500
B14: Annual Yield | C14: Calculation | D14: =D13*D12 -> 0 | F14: Electricity Rates
B15: Irradience Zone | C15: As per MCS Guide | D15: =VLOOKUP(D22,'MCS Irradiation Zones'!AN2:AO370,2,0) -> 10 | G15: Rate | H15: VAT | I15: Total
B16: Roof Pitch (Degrees) | C16: ⁰ | D16: 30 | F16: Average UK Electricity Rate | G16: 0.1672 | H16: =G16*0.05 -> 0.00836 | I16: =G16+H16 -> 0.17556
B17: Azimuth(Degrees) | C17: ⁰ | D17: 3.2 | F17: Average UK Standing Charge | G17: 0.212 | H17: =G17*0.05 -> 0.0106 | I17: =G17+H17 -> 0.2226
B18: Roof Type | C18: Option | D18: In Roof | I18: Use Above if Unknown
B19: Panels | C19: Option | D19: Blue
B20: Scaffold Required | C20: Option | D20: No
B21: Storage Size | C21: kW dc | D21: 0
B22: Postcode (Short) | C22: Option | D22: CR
B23: Title | C23: Text | D23: Mr/s
B24: First Name | C24: Text | D24: Kilian Seifert
B25: Last Name | C25: Text
B26: House Number | C26: Text | D26: 34
B27: Street Name | C27: Text | D27: Manor Way
B28: Town | C28: Text | D28: Mitcham
B29: Postcode | C29: Text | D29: CR4 1EE
B30: Telephone Number | C30: Number | D30: 07731894329
B31: Salesman Discount | C31: Free Entry | E31: Manager Approval Required Over £500
B32: Margin | C32: % | D32: 0.325 | E32: Must remain at 33% unless agreed with Manager
B33: VAT Level | C33: % | D33: 0.05
B34: Additional Item | C34: Choice | D34: None
B35: Additional Item | C35: Choice | D35: None
B36: Additional Item | C36: Choice | D36: None
B37: Additional Item | C37: Choice | D37: None | F37: System Size Bigger than 4kW | G37: Grid Application
F38: System Size Bigger than 10kW | G38: Grid Application 2
F39: System Size Bigger > 4kW but <5kW | G39: Sofar Solar 4000 HYD Hybrid Inverter
F40: System Size Bigger > 5kW but <6kW | G40: Sofar Solar 5000 HYD Hybrid Inverter
F41: System Size Bigger > 6kW but <7kW | G41: Sofar Solar 6000 HYD Hybrid Inverter

Sheet Your Proposal
A2: Your Quotation (Inclusive of VAT)
A3: =Costing!L37 -> 4077.6146
A4: PAYMENT TERMS
A5: Payment 1 @ 60% 14 Days prior to Installation Date | H5: =A3*60% -> 2446.5688
A6: Payment 2 @ 40% 7 days post Completion of Installation | H6: =A3*40% -> 1631.0458
A7: Estimated Years to Payback | H7: ='Usage and Savings'!N12 -> 20
A8: System Size (kWdc) | H8: =Costing!C1 -> 2.7
A9: Quantity of Panels | H9: =Input!D9&" Panels" -> 10 Panels
A10: Battery Storage Size | H10: =Input!D21&" kWdc" -> 0 kWdc
A11: BREAKDOWN OF PERFORMANCE
A12: Description | B12: Jan | C12: Feb | D12: Mar | E12: Apr | F12: May | G12: Jun | H12: Jul | I12: Aug | J12: Sep | K12: Oct | L12: Nov | M12: Dec | N12: Total
A13: Grid Usage | B13: =Calculation!KM3 -> 0 | C13: =Calculation!KN3 -> 0 | D13: =Calculation!KO3 -> 0 | E13: =Calculation!KP3 -> 0 | F13: =Calculation!KQ3 -> 0 | G13: =Calculation!KR3 -> 0 | H13: =Calculation!KS3 -> 0 | I13: =Calculation!KT3 -> 0 | ... M13: =Calculation!KX3 -> 0 | N13: =SUM(B13:M13) -> 0
A14: Solar Generation | B14: =Calculation!KM4 -> 0 | C14: =Calculation!KN4 -> 0 | D14: =Calculation!KO4 -> 0 | E14: =Calculation!KP4 -> 0 | F14: =Calculation!KQ4 -> 0 | G14: =Calculation!KR4 -> 0 | H14: =Calculation!KS4 -> 0 | I14: =Calculation!KT4 -> 0 | ... M14: =Calculation!KX4 -> 0 | N14: =SUM(B14:M14) -> 0
A15: Solar being Exported to Grid without Battery | B15: =Calculation!KM5 -> 0 | C15: =Calculation!KN5 -> 0 | D15: =Calculation!KO5 -> 0 | E15: =Calculation!KP5 -> 0 | F15: =Calculation!KQ5 -> 0 | G15: =Calculation!KR5 -> 0 | H15: =Calculation!KS5 -> 0 | I15: =Calculation!KT5 -> 0 | ... M15: =Calculation!KX5 -> 0 | N15: =SUM(B15:M15) -> 0
A16: Solar Being Used by Home without Battery | B16: =Calculation!KM6 -> 0 | C16: =Calculation!KN6 -> 0 | D16: =Calculation!KO6 -> 0 | E16: =Calculation!KP6 -> 0 | F16: =Calculation!KQ6 -> 0 | G16: =Calculation!KR6 -> 0 | H16: =Calculation!KS6 -> 0 | I16: =Calculation!KT6 -> 0 | ... M16: =Calculation!KX6 -> 0 | N16: =SUM(B16:M16) -> 0
A17: Grid Usage After Solar | B17: =Calculation!KM7 -> 0 | C17: =Calculation!KN7 -> 0 | D17: =Calculation!KO7 -> 0 | E17: =Calculation!KP7 -> 0 | F17: =Calculation!KQ7 -> 0 | G17: =Calculation!KR7 -> 0 | H17: =Calculation!KS7 -> 0 | I17: =Calculation!KT7 -> 0 | ... M17: =Calculation!KX7 -> 0 | N17: =SUM(B17:M17) -> 0
A18: Solar Being Exported to Grid With Battery | B18: =Calculation!KM8 -> 0 | C18: =Calculation!KN8 -> 0 | D18: =Calculation!KO8 -> 0 | E18: =Calculation!KP8 -> 0 | F18: =Calculation!KQ8 -> 0 | G18: =Calculation!KR8 -> 0 | H18: =Calculation!KS8 -> 0 | I18: =Calculation!KT8 -> 0 | ... M18: =Calculation!KX8 -> 0 | N18: =SUM(B18:M18) -> 0
A19: Solar Being Used by Home with Battery | B19: =Calculation!KM9 -> 0 | C19: =Calculation!KN9 -> 0 | D19: =Calculation!KO9 -> 0 | E19: =Calculation!KP9 -> 0 | F19: =Calculation!KQ9 -> 0 | G19: =Calculation!KR9 -> 0 | H19: =Calculation!KS9 -> 0 | I19: =Calculation!KT9 -> 0 | ... M19: =Calculation!KX9 -> 0 | N19: =SUM(B19:M19) -> 0
A20: Grid Usage After Solar and Battery | B20: =Calculation!KM10 -> 0 | C20: =Calculation!KN10 -> 0 | D20: =Calculation!KO10 -> 0 | E20: =Calculation!KP10 -> 0 | F20: =Calculation!KQ10 -> 0 | G20: =Calculation!KR10 -> 0 | H20: =Calculation!KS10 -> 0 | I20: =Calculation!KT10 -> 0 | ... M20: =Calculation!KX10 -> 0 | N20: =SUM(B20:M20) -> 0
A21: YOUR PREDICTED SYSTEM PERFORMANCE
A22: The Assumptions we have made are based on… | F22: Environmental Impact… | J22: Address and Climate Data…
A23: Predicted System Output | C23: Assumed Annual Inflation | D23: Assumed On-Site Energy Consumption | F23: CO² Savings | J23: Project Reference | L23: Postcode | M23: Irradience Zone | N23: Roof Pitch
A24: ='Usage and Savings'!B7 -> 0 kWh/annum | C24: ='Usage and Savings'!C7 -> 0.03 | D24: =Calculation!KZ9 -> #DIV/0! | F24: ='Usage and Savings'!E7 -> 0.517kg saved per PV kWh | J24: ='Usage and Savings'!F7 -> 44059 | L24: ='Usage and Savings'!G7 | M24: ='Usage and Savings'!H7 -> 10 | N24: ='Usage and Savings'!I7 -> 30⁰
A25: Our Proposal Installation Cost | C25: Assumed Energy Unit Cost | D25: Assumed Annual Energy Inflation | F25: CO² Savings Over 20 Years | J25: Address | M25: Irradiation Level | N25: Degree's From South
A26: =A3 -> 4077.6146 | C26: ='Usage and Savings'!C9 | D26: ='Usage and Savings'!D9 -> 0.04 | F26: ='Usage and Savings'!E9 -> 0 tonnes | J26: ='Usage and Savings'!F9 -> , , | M26: ='Usage and Savings'!H9 | N26: ='Usage and Savings'!I9 -> 0⁰
A27: YOUR PREDICTED SYSTEM PERFORMANCE 20 YEAR OUTLOOK
A28: Year | B28: Estimated Yearly Energy (kWh) | C28: Predicted Unit Cost Plus Inflation | D28: Predicted Annual Bills before Installation of Solar and Storage | F28: Estimated Generation (kWh) Of Solar System | G28: Collector Efficiency of Solar System | H28: Electricity Used on Site (kWh) from Solar & Storage | I28: Saving from Energy Used From Solar Consumed following Solar & Storage | K28: Predicted Annual Bills After Installation of Solar | L28: Return On Investment based on Savings from Solar and Storage System | N28: Accumulative Total
A29: 1 | B29: ='Usage and Savings'!C13 -> kWh | C29: ='Usage and Savings'!D13 | D29: ='Usage and Savings'!E13 -> 0 | F29: ='Usage and Savings'!F13 -> 0 | G29: ='Usage and Savings'!G13 -> 1 | H29: ='Usage and Savings'!H13 -> 0 | I29: ='Usage and Savings'!I13 -> 0 | K29: ='Usage and Savings'!J13 -> 0 | L29: ='Usage and Savings'!K13 -> -4077.6146 | N29: ='Usage and Savings'!L13 -> 0
A30: 2 | B30: ='Usage and Savings'!C14 -> kWh | C30: ='Usage and Savings'!D14 -> 0 | D30: ='Usage and Savings'!E14 -> 0 | F30: ='Usage and Savings'!F14 -> 0 | G30: ='Usage and Savings'!G14 -> 0.995 | H30: ='Usage and Savings'!H14 -> 0 | I30: ='Usage and Savings'!I14 -> 0 | K30: ='Usage and Savings'!J14 -> 0 | L30: ='Usage and Savings'!K14 -> -4077.6146 | N30: ='Usage and Savings'!L14 -> 0
A31: 3 | B31: ='Usage and Savings'!C15 -> kWh | C31: ='Usage and Savings'!D15 -> 0 | D31: ='Usage and Savings'!E15 -> 0 | F31: ='Usage and Savings'!F15 -> 0 | G31: ='Usage and Savings'!G15 -> 0.99 | H31: ='Usage and Savings'!H15 -> 0 | I31: ='Usage and Savings'!I15 -> 0 | K31: ='Usage and Savings'!J15 -> 0 | L31: ='Usage and Savings'!K15 -> -4077.6146 | N31: ='Usage and Savings'!L15 -> 0
A32: 4 | B32: ='Usage and Savings'!C16 -> kWh | C32: ='Usage and Savings'!D16 -> 0 | D32: ='Usage and Savings'!E16 -> 0 | F32: ='Usage and Savings'!F16 -> 0 | G32: ='Usage and Savings'!G16 -> 0.985 | H32: ='Usage and Savings'!H16 -> 0 | I32: ='Usage and Savings'!I16 -> 0 | K32: ='Usage and Savings'!J16 -> 0 | L32: ='Usage and Savings'!K16 -> -4077.6146 | N32: ='Usage and Savings'!L16 -> 0
A33: 5 | B33: ='Usage and Savings'!C17 -> kWh | C33: ='Usage and Savings'!D17 -> 0 | D33: ='Usage and Savings'!E17 -> 0 | F33: ='Usage and Savings'!F17 -> 0 | G33: ='Usage and Savings'!G17 -> 0.98 | H33: ='Usage and Savings'!H17 -> 0 | I33: ='Usage and Savings'!I17 -> 0 | K33: ='Usage and Savings'!J17 -> 0 | L33: ='Usage and Savings'!K17 -> -4077.6146 | N33: ='Usage and Savings'!L17 -> 0
A34: 6 | B34: ='Usage and Savings'!C18 -> kWh | C34: ='Usage and Savings'!D18 -> 0 | D34: ='Usage and Savings'!E18 -> 0 | F34: ='Usage and Savings'!F18 -> 0 | G34: ='Usage and Savings'!G18 -> 0.975 | H34: ='Usage and Savings'!H18 -> 0 | I34: ='Usage and Savings'!I18 -> 0 | K34: ='Usage and Savings'!J18 -> 0 | L34: ='Usage and Savings'!K18 -> -4077.6146 | N34: ='Usage and Savings'!L18 -> 0
A35: 7 | B35: ='Usage and Savings'!C19 -> kWh | C35: ='Usage and Savings'!D19 -> 0 | D35: ='Usage and Savings'!E19 -> 0 | F35: ='Usage and Savings'!F19 -> 0 | G35: ='Usage and Savings'!G19 -> 0.97 | H35: ='Usage and Savings'!H19 -> 0 | I35: ='Usage and Savings'!I19 -> 0 | K35: ='Usage and Savings'!J19 -> 0 | L35: ='Usage and Savings'!K19 -> -4077.6146 | N35: ='Usage and Savings'!L19 -> 0
A36: 8 | B36: ='Usage and Savings'!C20 -> kWh | C36: ='Usage and Savings'!D20 -> 0 | D36: ='Usage and Savings'!E20 -> 0 | F36: ='Usage and Savings'!F20 -> 0 | G36: ='Usage and Savings'!G20 -> 0.965 | H36: ='Usage and Savings'!H20 -> 0 | I36: ='Usage and Savings'!I20 -> 0 | K36: ='Usage and Savings'!J20 -> 0 | L36: ='Usage and Savings'!K20 -> -4077.6146 | N36: ='Usage and Savings'!L20 -> 0
A37: 9 | B37: ='Usage and Savings'!C21 -> kWh | C37: ='Usage and Savings'!D21 -> 0 | D37: ='Usage and Savings'!E21 -> 0 | F37: ='Usage and Savings'!F21 -> 0 | G37: ='Usage and Savings'!G21 -> 0.96 | H37: ='Usage and Savings'!H21 -> 0 | I37: ='Usage and Savings'!I21 -> 0 | K37: ='Usage and Savings'!J21 -> 0 | L37: ='Usage and Savings'!K21 -> -4077.6146 | N37: ='Usage and Savings'!L21 -> 0
A38: 10 | B38: ='Usage and Savings'!C22 -> kWh | C38: ='Usage and Savings'!D22 -> 0 | D38: ='Usage and Savings'!E22 -> 0 | F38: ='Usage and Savings'!F22 -> 0 | G38: ='Usage and Savings'!G22 -> 0.955 | H38: ='Usage and Savings'!H22 -> 0 | I38: ='Usage and Savings'!I22 -> 0 | K38: ='Usage and Savings'!J22 -> 0 | L38: ='Usage and Savings'!K22 -> -4077.6146 | N38: ='Usage and Savings'!L22 -> 0
A39: 11 | B39: ='Usage and Savings'!C23 -> kWh | C39: ='Usage and Savings'!D23 -> 0 | D39: ='Usage and Savings'!E23 -> 0 | F39: ='Usage and Savings'!F23 -> 0 | G39: ='Usage and Savings'!G23 -> 0.95 | H39: ='Usage and Savings'!H23 -> 0 | I39: ='Usage and Savings'!I23 -> 0 | K39: ='Usage and Savings'!J23 -> 0 | L39: ='Usage and Savings'!K23 -> -4077.6146 | N39: ='Usage and Savings'!L23 -> 0
A40: 12 | B40: ='Usage and Savings'!C24 -> kWh | C40: ='Usage and Savings'!D24 -> 0 | D40: ='Usage and Savings'!E24 -> 0 | F40: ='Usage and Savings'!F24 -> 0 | G40: ='Usage and Savings'!G24 -> 0.945 | H40: ='Usage and Savings'!H24 -> 0 | I40: ='Usage and Savings'!I24 -> 0 | K40: ='Usage and Savings'!J24 -> 0 | L40: ='Usage and Savings'!K24 -> -4077.6146 | N40: ='Usage and Savings'!L24 -> 0
... A48: 20 | B48: ='Usage and Savings'!C32 -> kWh | C48: ='Usage and Savings'!D32 -> 0 | D48: ='Usage and Savings'!E32 -> 0 | F48: ='Usage and Savings'!F32 -> 0 | G48: ='Usage and Savings'!G32 -> 0.905 | H48: ='Usage and Savings'!H32 -> 0 | I48: ='Usage and Savings'!I32 -> 0 | K48: ='Usage and Savings'!J32 -> 0 | L48: ='Usage and Savings'!K32 -> -4077.6146 | N48: ='Usage and Savings'!L32 -> 0
...

Sheet Online Sales Pack
A1: Your Quotation (Inclusive of VAT)
A2: =Costing!L37 -> 4077.6146
A3: PAYMENT TERMS
A4: Payment 1 @ 60% 14 Days prior to Installation Date | H4: =A2*60% -> 2446.5688
A5: Payment 2 @ 40% 7 days post Completion of Installation | H5: =A2*40% -> 1631.0458
A6: Estimated Years to Payback | H6: ='Usage and Savings'!N12 -> 20
A7: System Size (kWdc) | H7: =Costing!C1 -> 2.7
A8: Quantity of Panels | H8: =Input!D9&" Panels" -> 10 Panels
A9: Battery Storage Size | H9: =Input!D21&" kWdc" -> 0 kWdc
A10: BREAKDOWN OF PERFORMANCE
A11: Description | B11: Jan | C11: Feb | D11: Mar | E11: Apr | F11: May | G11: Jun | H11: Jul | I11: Aug | J11: Sep | K11: Oct | L11: Nov | M11: Dec | N11: Total
A12: Grid Usage | B12: =Calculation!KM3 -> 0 | C12: =Calculation!KN3 -> 0 | D12: =Calculation!KO3 -> 0 | E12: =Calculation!KP3 -> 0 | F12: =Calculation!KQ3 -> 0 | G12: =Calculation!KR3 -> 0 | H12: =Calculation!KS3 -> 0 | I12: =Calculation!KT3 -> 0 | ... M12: =Calculation!KX3 -> 0 | N12: =SUM(B12:M12) -> 0
A13: Solar Generation | B13: =Calculation!KM4 -> 0 | C13: =Calculation!KN4 -> 0 | D13: =Calculation!KO4 -> 0 | E13: =Calculation!KP4 -> 0 | F13: =Calculation!KQ4 -> 0 | G13: =Calculation!KR4 -> 0 | H13: =Calculation!KS4 -> 0 | I13: =Calculation!KT4 -> 0 | ... M13: =Calculation!KX4 -> 0 | N13: =SUM(B13:M13) -> 0
A14: Solar being Exported to Grid without Battery | B14: =Calculation!KM5 -> 0 | C14: =Calculation!KN5 -> 0 | D14: =Calculation!KO5 -> 0 | E14: =Calculation!KP5 -> 0 | F14: =Calculation!KQ5 -> 0 | G14: =Calculation!KR5 -> 0 | H14: =Calculation!KS5 -> 0 | I14: =Calculation!KT5 -> 0 | ... M14: =Calculation!KX5 -> 0 | N14: =SUM(B14:M14) -> 0
A15: Solar Being Used by Home without Battery | B15: =Calculation!KM6 -> 0 | C15: =Calculation!KN6 -> 0 | D15: =Calculation!KO6 -> 0 | E15: =Calculation!KP6 -> 0 | F15: =Calculation!KQ6 -> 0 | G15: =Calculation!KR6 -> 0 | H15: =Calculation!KS6 -> 0 | I15: =Calculation!KT6 -> 0 | ... M15: =Calculation!KX6 -> 0 | N15: =SUM(B15:M15) -> 0
A16: Grid Usage After Solar | B16: =Calculation!KM7 -> 0 | C16: =Calculation!KN7 -> 0 | D16: =Calculation!KO7 -> 0 | E16: =Calculation!KP7 -> 0 | F16: =Calculation!KQ7 -> 0 | G16: =Calculation!KR7 -> 0 | H16: =Calculation!KS7 -> 0 | I16: =Calculation!KT7 -> 0 | ... M16: =Calculation!KX7 -> 0 | N16: =SUM(B16:M16) -> 0
A17: Solar Being Exported to Grid With Battery | B17: =Calculation!KM8 -> 0 | C17: =Calculation!KN8 -> 0 | D17: =Calculation!KO8 -> 0 | E17: =Calculation!KP8 -> 0 | F17: =Calculation!KQ8 -> 0 | G17: =Calculation!KR8 -> 0 | H17: =Calculation!KS8 -> 0 | I17: =Calculation!KT8 -> 0 | ... M17: =Calculation!KX8 -> 0 | N17: =SUM(B17:M17) -> 0
A18: Solar Being Used by Home with Battery | B18: =Calculation!KM9 -> 0 | C18: =Calculation!KN9 -> 0 | D18: =Calculation!KO9 -> 0 | E18: =Calculation!KP9 -> 0 | F18: =Calculation!KQ9 -> 0 | G18: =Calculation!KR9 -> 0 | H18: =Calculation!KS9 -> 0 | I18: =Calculation!KT9 -> 0 | ... M18: =Calculation!KX9 -> 0 | N18: =SUM(B18:M18) -> 0
A19: Grid Usage After Solar and Battery | B19: =Calculation!KM10 -> 0 | C19: =Calculation!KN10 -> 0 | D19: =Calculation!KO10 -> 0 | E19: =Calculation!KP10 -> 0 | F19: =Calculation!KQ10 -> 0 | G19: =Calculation!KR10 -> 0 | H19: =Calculation!KS10 -> 0 | I19: =Calculation!KT10 -> 0 | ... M19: =Calculation!KX10 -> 0 | N19: =SUM(B19:M19) -> 0
A20: YOUR PREDICTED SYSTEM PERFORMANCE
A21: The Assumptions we have made are based on… | F21: Environmental Impact… | J21: Address and Climate Data…
A22: Predicted System Output | C22: Assumed Annual Inflation | D22: Assumed On-Site Energy Consumption | F22: CO² Savings | J22: Project Reference | L22: Postcode | M22: Irradience Zone | N22: Roof Pitch
A23: ='Usage and Savings'!B7 -> 0 kWh/annum | C23: ='Usage and Savings'!C7 -> 0.03 | D23: =Calculation!KZ9 -> #DIV/0! | F23: ='Usage and Savings'!E7 -> 0.517kg saved per PV kWh | J23: ='Usage and Savings'!F7 -> 44059 | L23: ='Usage and Savings'!G7 | M23: ='Usage and Savings'!H7 -> 10 | N23: ='Usage and Savings'!I7 -> 30⁰
A24: Our Proposal Installation Cost | C24: Assumed Energy Unit Cost | D24: Assumed Annual Energy Inflation | F24: CO² Savings Over 20 Years | J24: Address | M24: Irradiation Level | N24: Degree's From South
A25: =A2 -> 4077.6146 | C25: ='Usage and Savings'!C9 | D25: ='Usage and Savings'!D9 -> 0.04 | F25: ='Usage and Savings'!E9 -> 0 tonnes | J25: ='Usage and Savings'!F9 -> , , | M25: ='Usage and Savings'!H9 | N25: ='Usage and Savings'!I9 -> 0⁰
A26: YOUR PREDICTED SYSTEM PERFORMANCE 20 YEAR OUTLOOK
A27: Year | B27: Estimated Yearly Energy (kWh) | C27: Predicted Unit Cost Plus Inflation | D27: Predicted Annual Bills before Installation of Solar and Storage | F27: Estimated Generation (kWh) Of Solar System | G27: Collector Efficiency of Solar System | H27: Electricity Used on Site (kWh) from Solar & Storage | I27: Saving from Energy Used From Solar Consumed following Solar & Storage | K27: Predicted Annual Bills After Installation of Solar | L27: Return On Investment based on Savings from Solar and Storage System | N27: Accumulative Total
A28: 1 | B28: ='Usage and Savings'!C13 -> kWh | C28: ='Usage and Savings'!D13 | D28: ='Usage and Savings'!E13 -> 0 | F28: ='Usage and Savings'!F13 -> 0 | G28: ='Usage and Savings'!G13 -> 1 | H28: ='Usage and Savings'!H13 -> 0 | I28: ='Usage and Savings'!I13 -> 0 | K28: ='Usage and Savings'!J13 -> 0 | L28: ='Usage and Savings'!K13 -> -4077.6146 | N28: ='Usage and Savings'!L13 -> 0
A29: 2 | B29: ='Usage and Savings'!C14 -> kWh | C29: ='Usage and Savings'!D14 -> 0 | D29: ='Usage and Savings'!E14 -> 0 | F29: ='Usage and Savings'!F14 -> 0 | G29: ='Usage and Savings'!G14 -> 0.995 | H29: ='Usage and Savings'!H14 -> 0 | I29: ='Usage and Savings'!I14 -> 0 | K29: ='Usage and Savings'!J14 -> 0 | L29: ='Usage and Savings'!K14 -> -4077.6146 | N29: ='Usage and Savings'!L14 -> 0
A30: 3 | B30: ='Usage and Savings'!C15 -> kWh | C30: ='Usage and Savings'!D15 -> 0 | D30: ='Usage and Savings'!E15 -> 0 | F30: ='Usage and Savings'!F15 -> 0 | G30: ='Usage and Savings'!G15 -> 0.99 | H30: ='Usage and Savings'!H15 -> 0 | I30: ='Usage and Savings'!I15 -> 0 | K30: ='Usage and Savings'!J15 -> 0 | L30: ='Usage and Savings'!K15 -> -4077.6146 | N30: ='Usage and Savings'!L15 -> 0
A31: 4 | B31: ='Usage and Savings'!C16 -> kWh | C31: ='Usage and Savings'!D16 -> 0 | D31: ='Usage and Savings'!E16 -> 0 | F31: ='Usage and Savings'!F16 -> 0 | G31: ='Usage and Savings'!G16 -> 0.985 | H31: ='Usage and Savings'!H16 -> 0 | I31: ='Usage and Savings'!I16 -> 0 | K31: ='Usage and Savings'!J16 -> 0 | L31: ='Usage and Savings'!K16 -> -4077.6146 | N31: ='Usage and Savings'!L16 -> 0
A32: 5 | B32: ='Usage and Savings'!C17 -> kWh | C32: ='Usage and Savings'!D17 -> 0 | D32: ='Usage and Savings'!E17 -> 0 | F32: ='Usage and Savings'!F17 -> 0 | G32: ='Usage and Savings'!G17 -> 0.98 | H32: ='Usage and Savings'!H17 -> 0 | I32: ='Usage and Savings'!I17 -> 0 | K32: ='Usage and Savings'!J17 -> 0 | L32: ='Usage and Savings'!K17 -> -4077.6146 | N32: ='Usage and Savings'!L17 -> 0
A33: 6 | B33: ='Usage and Savings'!C18 -> kWh | C33: ='Usage and Savings'!D18 -> 0 | D33: ='Usage and Savings'!E18 -> 0 | F33: ='Usage and Savings'!F18 -> 0 | G33: ='Usage and Savings'!G18 -> 0.975 | H33: ='Usage and Savings'!H18 -> 0 | I33: ='Usage and Savings'!I18 -> 0 | K33: ='Usage and Savings'!J18 -> 0 | L33: ='Usage and Savings'!K18 -> -4077.6146 | N33: ='Usage and Savings'!L18 -> 0
A34: 7 | B34: ='Usage and Savings'!C19 -> kWh | C34: ='Usage and Savings'!D19 -> 0 | D34: ='Usage and Savings'!E19 -> 0 | F34: ='Usage and Savings'!F19 -> 0 | G34: ='Usage and Savings'!G19 -> 0.97 | H34: ='Usage and Savings'!H19 -> 0 | I34: ='Usage and Savings'!I19 -> 0 | K34: ='Usage and Savings'!J19 -> 0 | L34: ='Usage and Savings'!K19 -> -4077.6146 | N34: ='Usage and Savings'!L19 -> 0
A35: 8 | B35: ='Usage and Savings'!C20 -> kWh | C35: ='Usage and Savings'!D20 -> 0 | D35: ='Usage and Savings'!E20 -> 0 | F35: ='Usage and Savings'!F20 -> 0 | G35: ='Usage and Savings'!G20 -> 0.965 | H35: ='Usage and Savings'!H20 -> 0 | I35: ='Usage and Savings'!I20 -> 0 | K35: ='Usage and Savings'!J20 -> 0 | L35: ='Usage and Savings'!K20 -> -4077.6146 | N35: ='Usage and Savings'!L20 -> 0
A36: 9 | B36: ='Usage and Savings'!C21 -> kWh | C36: ='Usage and Savings'!D21 -> 0 | D36: ='Usage and Savings'!E21 -> 0 | F36: ='Usage and Savings'!F21 -> 0 | G36: ='Usage and Savings'!G21 -> 0.96 | H36: ='Usage and Savings'!H21 -> 0 | I36: ='Usage and Savings'!I21 -> 0 | K36: ='Usage and Savings'!J21 -> 0 | L36: ='Usage and Savings'!K21 -> -4077.6146 | N36: ='Usage and Savings'!L21 -> 0
A37: 10 | B37: ='Usage and Savings'!C22 -> kWh | C37: ='Usage and Savings'!D22 -> 0 | D37: ='Usage and Savings'!E22 -> 0 | F37: ='Usage and Savings'!F22 -> 0 | G37: ='Usage and Savings'!G22 -> 0.955 | H37: ='Usage and Savings'!H22 -> 0 | I37: ='Usage and Savings'!I22 -> 0 | K37: ='Usage and Savings'!J22 -> 0 | L37: ='Usage and Savings'!K22 -> -4077.6146 | N37: ='Usage and Savings'!L22 -> 0
A38: 11 | B38: ='Usage and Savings'!C23 -> kWh | C38: ='Usage and Savings'!D23 -> 0 | D38: ='Usage and Savings'!E23 -> 0 | F38: ='Usage and Savings'!F23 -> 0 | G38: ='Usage and Savings'!G23 -> 0.95 | H38: ='Usage and Savings'!H23 -> 0 | I38: ='Usage and Savings'!I23 -> 0 | K38: ='Usage and Savings'!J23 -> 0 | L38: ='Usage and Savings'!K23 -> -4077.6146 | N38: ='Usage and Savings'!L23 -> 0
A39: 12 | B39: ='Usage and Savings'!C24 -> kWh | C39: ='Usage and Savings'!D24 -> 0 | D39: ='Usage and Savings'!E24 -> 0 | F39: ='Usage and Savings'!F24 -> 0 | G39: ='Usage and Savings'!G24 -> 0.945 | H39: ='Usage and Savings'!H24 -> 0 | I39: ='Usage and Savings'!I24 -> 0 | K39: ='Usage and Savings'!J24 -> 0 | L39: ='Usage and Savings'!K24 -> -4077.6146 | N39: ='Usage and Savings'!L24 -> 0
... A47: 20 | B47: ='Usage and Savings'!C32 -> kWh | C47: ='Usage and Savings'!D32 -> 0 | D47: ='Usage and Savings'!E32 -> 0 | F47: ='Usage and Savings'!F32 -> 0 | G47: ='Usage and Savings'!G32 -> 0.905 | H47: ='Usage and Savings'!H32 -> 0 | I47: ='Usage and Savings'!I32 -> 0 | K47: ='Usage and Savings'!J32 -> 0 | L47: ='Usage and Savings'!K32 -> -4077.6146 | N47: ='Usage and Savings'!L32 -> 0
...

Sheet Costing
A1: Solar kW dc | C1: =Input!D12 -> 2.7 | D1: Roof Type | E1: =Input!D18 -> In Roof | F1: Scaffold Required | G1: =Input!D20 -> No | H1: Battery Size | I1: =Input!D21 -> 0 | J1: Margin | K1: =Input!D32 -> 0.325 | L1: VAT | M1: =Input!D33 -> 0.05 | N1: Discount | O1: =Input!D31
B2: Panel Quantity | C2: =Input!D9 -> 10 | D2: Panel Type | E2: =Input!D19 -> Blue | M2: =H27/($C$1*1000) -> 1.438312
A3: DO NOT EDIT THIS SECTION | B3: Description | C3: Type | D3: Cost Per KW | E3: Cost | F3: Cost Applied | G3: Margin | H3: Total Sale | I3: Pence Per W | J3: VAT | K3: Total Sale Inc VAT | M3: =K27/($C$1*1000) -> 1.5102276
B4: Concrete Roof | C4: Concrete | D4: 75.59 | E4: =D4*$C$1 -> 204.093 | F4: =SUMIFS(E4,C4,$E$1) -> 0 | G4: =F4*$K$1 -> 0 | H4: =SUM(F4:G4) -> 0 | I4: =H4/($C$1*1000) -> 0 | J4: =H4*$M$1 -> 0 | K4: =J4+H4 -> 0 | M4: =F27/($C$1*1000) -> 1.0855185
B5: Slate Roof | C5: Slate | D5: 90.59 | E5: =D5*$C$1 -> 244.593 | F5: =SUMIFS(E5,C5,$E$1) -> 0 | G5: =F5*$K$1 -> 0 | H5: =SUM(F5:G5) -> 0 | I5: =H5/($C$1*1000) -> 0 | J5: =H5*$M$1 -> 0 | K5: =J5+H5 -> 0
B6: Rosemary Roof | C6: Rosemary | D6: 90.59 | E6: =D6*$C$1 -> 244.593 | F6: =SUMIFS(E6,C6,$E$1) -> 0 | G6: =F6*$K$1 -> 0 | H6: =SUM(F6:G6) -> 0 | I6: =H6/($C$1*1000) -> 0 | J6: =H6*$M$1 -> 0 | K6: =J6+H6 -> 0
B7: Flat Roof | C7: Flat Roof | D7: 125 | E7: =D7*$C$1 -> 337.5 | F7: =SUMIFS(E7,C7,$E$1) -> 0 | G7: =F7*$K$1 -> 0 | H7: =SUM(F7:G7) -> 0 | I7: =H7/($C$1*1000) -> 0 | J7: =H7*$M$1 -> 0 | K7: =J7+H7 -> 0
B8: Ground Mounted | C8: Ground Mounted | D8: 130 | E8: =D8*$C$1 -> 351 | F8: =SUMIFS(E8,C8,$E$1) -> 0 | G8: =F8*$K$1 -> 0 | H8: =SUM(F8:G8) -> 0 | I8: =H8/($C$1*1000) -> 0 | J8: =H8*$M$1 -> 0 | K8: =J8+H8 -> 0
B9: In Roof | C9: In Roof | D9: 60 | E9: =D9*C2 -> 600 | F9: =SUMIFS(E9,C9,$E$1) -> 600 | G9: =F9*$K$1 -> 195 | H9: =SUM(F9:G9) -> 795 | I9: =H9/($C$1*1000) -> 0.29444444 | J9: =H9*$M$1 -> 39.75 | K9: =J9+H9 -> 834.75
B10: Dekra Roof | C10: Dekra | D10: 80.59 | E10: =D10*$C$1 -> 217.593 | F10: =SUMIFS(E10,C10,$E$1) -> 0 | G10: =F10*$K$1 -> 0 | H10: =SUM(F10:G10) -> 0 | I10: =H10/($C$1*1000) -> 0 | J10: =H10*$M$1 -> 0 | K10: =J10+H10 -> 0
B11: Ancillary Materials | C11: Per KW | D11: 40 | E11: =D11*$C$1 -> 108 | F11: =E11 -> 108 | G11: =F11*$K$1 -> 35.1 | H11: =SUM(F11:G11) -> 143.1 | I11: =H11/($C$1*1000) -> 0.053 | J11: =H11*$M$1 -> 7.155 | K11: =J11+H11 -> 150.255 | M11: Module Cost
B12: Solar Modules Blue | C12: Blue | D12: 210 | E12: =D12*$C$1 -> 567 | F12: =SUMIFS(E12,C12,$E$2) -> 567 | G12: =F12*$K$1 -> 184.275 | H12: =SUM(F12:G12) -> 751.275 | I12: =H12/($C$1*1000) -> 0.27825 | J12: =H12*$M$1 -> 37.56375 | K12: =J12+H12 -> 788.83875 | M12: =E12/C$2 -> 56.7
B13: Solar Modules Black | C13: Black | D13: 260 | E13: =D13*$C$1 -> 702 | F13: =SUMIFS(E13,C13,$E$2) -> 0 | G13: =F13*$K$1 -> 0 | H13: =SUM(F13:G13) -> 0 | I13: =H13/($C$1*1000) -> 0 | J13: =H13*$M$1 -> 0 | K13: =J13+H13 -> 0 | M13: =E13/C$2 -> 70.2
B14: Inverter | C14: Per KW | D14: 92 | E14: =D14*$C$1 -> 248.4 | F14: =E14 -> 248.4 | G14: =F14*$K$1 -> 80.73 | H14: =SUM(F14:G14) -> 329.13 | I14: =H14/($C$1*1000) -> 0.1219 | J14: =H14*$M$1 -> 16.4565 | K14: =J14+H14 -> 345.5865
B15: Metering Equipment | C15: Per Job | D15: N/A | E15: 120.5 | F15: =E15 -> 120.5 | G15: =F15*$K$1 -> 39.1625 | H15: =SUM(F15:G15) -> 159.6625 | I15: =H15/($C$1*1000) -> 0.059134259 | J15: =H15*$M$1 -> 7.983125 | K15: =J15+H15 -> 167.64562
B16: Battery Equipment 3KW | C16: 2.5 | D16: N/A | E16: =480+370 -> 850 | F16: =SUMIFS(E16,C16,$I$1) -> 0 | G16: =F16*$K$1 -> 0 | H16: =SUM(F16:G16) -> 0 | I16: =H16/($C$1*1000) -> 0 | J16: =H16*$M$1 -> 0 | K16: =J16+H16 -> 0
B17: Battery Equipment 5KW | C17: 5 | D17: N/A | E17: =960+370 -> 1330 | F17: =SUMIFS(E17,C17,$I$1) -> 0 | G17: =F17*$K$1 -> 0 | H17: =SUM(F17:G17) -> 0 | I17: =H17/($C$1*1000) -> 0 | J17: =H17*$M$1 -> 0 | K17: =J17+H17 -> 0
B18: Battery Equipment 7.5KW | C18: 7.5 | D18: N/A | E18: =1480+370 -> 1850 | F18: =SUMIFS(E18,C18,$I$1) -> 0 | G18: =F18*$K$1 -> 0 | H18: =SUM(F18:G18) -> 0 | I18: =H18/($C$1*1000) -> 0 | J18: =H18*$M$1 -> 0 | K18: =J18+H18 -> 0
B19: Battery Equipment 10KW | C19: 10 | D19: N/A | E19: =1960+370 -> 2330 | F19: =SUMIFS(E19,C19,$I$1) -> 0 | G19: =F19*$K$1 -> 0 | H19: =SUM(F19:G19) -> 0 | I19: =H19/($C$1*1000) -> 0 | J19: =H19*$M$1 -> 0 | K19: =J19+H19 -> 0
B20: Labour | C20: Per KW | D20: 160 | E20: =D20*$C$1 -> 432 | F20: =E20 -> 432 | G20: =F20*$K$1 -> 140.4 | H20: =SUM(F20:G20) -> 572.4 | I20: =H20/($C$1*1000) -> 0.212 | J20: =H20*$M$1 -> 28.62 | K20: =J20+H20 -> 601.02
B21: Scaffold | C21: Per Job | D21: N/A | E21: 500 | F21: =SUMIFS(E21,G1,"Yes") -> 0 | G21: =F21*$K$1 -> 0 | H21: =SUM(F21:G21) -> 0 | I21: =H21/($C$1*1000) -> 0 | J21: =H21*$M$1 -> 0 | K21: =J21+H21 -> 0
B22: H&S and Project Management | C22: Per Job | D22: N/A | E22: 50 | F22: =E22 -> 50 | G22: =F22*$K$1 -> 16.25 | H22: =SUM(F22:G22) -> 66.25 | I22: =H22/($C$1*1000) -> 0.024537037 | J22: =H22*$M$1 -> 3.3125 | K22: =(J22+H22) -> 69.5625
B23: Commissioning | C23: Per Job | D23: N/A | E23: =50 -> 50 | F23: =E23 -> 50 | G23: =F23*$K$1 -> 16.25 | H23: =SUM(F23:G23) -> 66.25 | I23: =H23/($C$1*1000) -> 0.024537037 | J23: =H23*$M$1 -> 3.3125 | K23: =(J23+H23) -> 69.5625
B24: Packaging and Delivery | C24: Per Job | D24: N/A | E24: =150 -> 150 | F24: =E24 -> 150 | G24: =F24*$K$1 -> 48.75 | H24: =SUM(F24:G24) -> 198.75 | I24: =H24/($C$1*1000) -> 0.073611111 | J24: =H24*$M$1 -> 9.9375 | K24: =(J24+H24) -> 208.6875
B25: Administration / Lead Fees | C25: Per Job | D25: N/A | E25: 500 | F25: =E25 -> 500 | G25: =F25*$K$1 -> 162.5 | H25: =SUM(F25:G25) -> 662.5 | I25: =H25/($C$1*1000) -> 0.24537037 | J25: =H25*$M$1 -> 33.125 | K25: =(J25+H25) -> 695.625
B26: Registrations | C26: Per Job | D26: N/A | E26: =35+70 -> 105 | F26: =E26 -> 105 | G26: =F26*$K$1 -> 34.125 | H26: =SUM(F26:G26) -> 139.125 | I26: =H26/($C$1*1000) -> 0.051527778 | J26: =H26*$M$1 -> 6.95625 | K26: =(J26+H26) -> 146.08125
F27: =SUM(F4:F26) -> 2930.9 | G27: =SUM(G4:G26) -> 952.5425 | H27: =SUM(H4:H26) -> 3883.4425 | I27: =H27/($C$1*1000) -> 1.438312 | J27: =SUM(J4:J26) -> 194.17212 | K27: =SUM(K4:K26) -> 4077.6146
A29: ADD UPLIFT AND ADDITIONAL ITEMS IN YELLOW ONLY | B29: Additional Items | C29: Type | E29: Cost | G29: Margin | H29: Total Sale | I29: VAT Rate | K29: VAT | L29: Total Sale Inc VAT
B30: =Input!D34 -> None | C30: =VLOOKUP(B30,'Lookup Data'!A:B,2,0) -> None | E30: =VLOOKUP(B30,'Lookup Data'!A:C,3,0) -> 0 | G30: =E30*$K$1 -> 0 | H30: =G30+E30 -> 0 | I30: 0.05 | K30: =H30*I30 -> 0 | L30: =I30+H30 -> 0.05
B31: =Input!D35 -> None | C31: =VLOOKUP(B31,'Lookup Data'!A:B,2,0) -> None | E31: =VLOOKUP(B31,'Lookup Data'!A:C,3,0) -> 0 | G31: =E31*$K$1 -> 0 | H31: =G31+E31 -> 0 | I31: =VLOOKUP(B31,'Lookup Data'!A:D,4,0) -> 0 | K31: =H31*I31 -> 0 | L31: =I31+H31 -> 0
B32: =Input!D36 -> None | C32: =VLOOKUP(B32,'Lookup Data'!A:B,2,0) -> None | E32: =VLOOKUP(B32,'Lookup Data'!A:C,3,0) -> 0 | G32: =E32*$K$1 -> 0 | H32: =G32+E32 -> 0 | I32: =VLOOKUP(B32,'Lookup Data'!A:D,4,0) -> 0 | K32: =H32*I32 -> 0 | L32: =I32+H32 -> 0
B33: =Input!D37 -> None | C33: =VLOOKUP(B33,'Lookup Data'!A:B,2,0) -> None | E33: =VLOOKUP(B33,'Lookup Data'!A:C,3,0) -> 0 | G33: =E33*$K$1 -> 0 | H33: =G33+E33 -> 0 | I33: =VLOOKUP(B33,'Lookup Data'!A:D,4,0) -> 0 | K33: =H33*I33 -> 0 | L33: =I33+H33 -> 0
E34: =SUM(E30:E33) -> 0 | G34: =SUM(G30:G33) -> 0 | H34: =SUM(H30:H33) -> 0 | I34: 0 | K34: =SUM(K30:K33) -> 0 | L34: =I34+H34 -> 0
E35: Total Cost | G35: Total Margin | H35: Total Sale | K35: Total VAT | L35: Total Sale Inc VAT
E36: Places for People Fee | H36: =-Input!D31 -> 0
E37: =F27+F34 -> 2930.9 | G37: =G27+G34-G36 -> 952.5425 | H37: =H27+H34+H36 -> 3883.4425 | K37: =H37*5% -> 194.17212 | L37: =K37+H37 -> 4077.6146

Sheet Usage and Savings
B2: Predicted System Performance
B4: The Assumptions we have made are based on… | E4: Environmental Impact… | F4: Address and Climate Data…
B6: Predicted System Output | C6: Assumed Annual Inflation (RPI) | D6: Assumed On-Site Energy Consumption | E6: CO² Savings | F6: Project Reference | G6: Postcode | H6: Irradience Zone | I6: Roof Pitch
B7: =Input!D14&" "&"kWh/annum" -> 0 kWh/annum | C7: 0.03 | D7: =H13 -> 0 | E7: 0.517kg saved per PV kWh | F7: =Input!D3 -> 44059 | G7: =Input!D29 | H7: =Input!D15 -> 10 | I7: =Input!D16&Input!C16 -> 30⁰
B8: Our Proposal Installation Cost | C8: Assumed Energy Unit Cost | D8: Assumed Annual Energy Inflation | E8: CO² Savings Over 20 Years | F8: Address | H8: Irradiation Level | I8: Degrees From South
B9: ="£"&(ROUNDUP(#REF!,2))&" Inc VAT" -> #REF! | C9: =Input!D6 | D9: 0.04 | E9: =(ROUND(((SUM(F13:F32)*0.517)/1000),2)&" tonnes") -> 0 tonnes | F9: =Input!D26&Input!E25&Input!D27&", "&Input!D28&", "&Input!D29 -> , , | H9: =Input!D13 | I9: =Input!D17&Input!C17 -> 0⁰
B11: Your predicted system performance 20 year outlook
B12: Year | C12: Estimated Yearly Energy (kWh) | D12: Predicted Unit Cost Plus Inflation | E12: Predicted Annual Bills before Installation of Solar and Storage | F12: Estimated Generation (kWh) Of Solar System | G12: Collector Efficiency of Solar System | H12: Electricity Used on Site (kWh) from Solar & Storage | I12: Saving from Energy Used From Solar Consumed following Solar & Storage | J12: Predicted Annual Bills After Installation of Solar | K12: Return On Investment based on Savings from Solar and Storage System | L12: Accumulative Total | N12: =COUNTIF(K13:K32,"<0.00001") -> 20
B13: 1 | C13: =Input!D5&" kWh" -> kWh | D13: =Input!D6 | E13: =(D13*Input!$D$5)+(365*Input!$D$7) -> 0 | F13: =Input!$D$14*G13 -> 0 | G13: 1 | H13: =Calculation!$KY$9 -> 0 | I13: =H13*D13 -> 0 | J13: =E13-I13 -> 0 | K13: =-Costing!L37+I13 -> -4077.6146 | L13: =I13 -> 0
B14: 2 | C14: =C13 -> kWh | D14: =(D13+(D13*$D$9)) -> 0 | E14: =(D14*Input!$D$5)+(365*Input!$D$7) -> 0 | F14: =Input!$D$14*G14 -> 0 | G14: =G13-0.005 -> 0.995 | H14: =Calculation!$KY$9 -> 0 | I14: =H14*D14 -> 0 | J14: =E14-I14 -> 0 | K14: =K13+I14 -> -4077.6146 | L14: =L13+I14 -> 0
B15: 3 | C15: =C14 -> kWh | D15: =(D14+(D14*$D$9)) -> 0 | E15: =(D15*Input!$D$5)+(365*Input!$D$7) -> 0 | F15: =Input!$D$14*G15 -> 0 | G15: =G14-0.005 -> 0.99 | H15: =Calculation!$KY$9 -> 0 | I15: =H15*D15 -> 0 | J15: =E15-I15 -> 0 | K15: =K14+I15 -> -4077.6146 | L15: =L14+I15 -> 0
B16: 4 | C16: =C15 -> kWh | D16: =(D15+(D15*$D$9)) -> 0 | E16: =(D16*Input!$D$5)+(365*Input!$D$7) -> 0 | F16: =Input!$D$14*G16 -> 0 | G16: =G15-0.005 -> 0.985 | H16: =Calculation!$KY$9 -> 0 | I16: =H16*D16 -> 0 | J16: =E16-I16 -> 0 | K16: =K15+I16 -> -4077.6146 | L16: =L15+I16 -> 0
B17: 5 | C17: =C16 -> kWh | D17: =(D16+(D16*$D$9)) -> 0 | E17: =(D17*Input!$D$5)+(365*Input!$D$7) -> 0 | F17: =Input!$D$14*G17 -> 0 | G17: =G16-0.005 -> 0.98 | H17: =Calculation!$KY$9 -> 0 | I17: =H17*D17 -> 0 | J17: =E17-I17 -> 0 | K17: =K16+I17 -> -4077.6146 | L17: =L16+I17 -> 0
B18: 6 | C18: =C17 -> kWh | D18: =(D17+(D17*$D$9)) -> 0 | E18: =(D18*Input!$D$5)+(365*Input!$D$7) -> 0 | F18: =Input!$D$14*G18 -> 0 | G18: =G17-0.005 -> 0.975 | H18: =Calculation!$KY$9 -> 0 | I18: =H18*D18 -> 0 | J18: =E18-I18 -> 0 | K18: =K17+I18 -> -4077.6146 | L18: =L17+I18 -> 0
B19: 7 | C19: =C18 -> kWh | D19: =(D18+(D18*$D$9)) -> 0 | E19: =(D19*Input!$D$5)+(365*Input!$D$7) -> 0 | F19: =Input!$D$14*G19 -> 0 | G19: =G18-0.005 -> 0.97 | H19: =Calculation!$KY$9 -> 0 | I19: =H19*D19 -> 0 | J19: =E19-I19 -> 0 | K19: =K18+I19 -> -4077.6146 | L19: =L18+I19 -> 0
B20: 8 | C20: =C19 -> kWh | D20: =(D19+(D19*$D$9)) -> 0 | E20: =(D20*Input!$D$5)+(365*Input!$D$7) -> 0 | F20: =Input!$D$14*G20 -> 0 | G20: =G19-0.005 -> 0.965 | H20: =Calculation!$KY$9 -> 0 | I20: =H20*D20 -> 0 | J20: =E20-I20 -> 0 | K20: =K19+I20 -> -4077.6146 | L20: =L19+I20 -> 0
B21: 9 | C21: =C20 -> kWh | D21: =(D20+(D20*$D$9)) -> 0 | E21: =(D21*Input!$D$5)+(365*Input!$D$7) -> 0 | F21: =Input!$D$14*G21 -> 0 | G21: =G20-0.005 -> 0.96 | H21: =Calculation!$KY$9 -> 0 | I21: =H21*D21 -> 0 | J21: =E21-I21 -> 0 | K21: =K20+I21 -> -4077.6146 | L21: =L20+I21 -> 0
B22: 10 | C22: =C21 -> kWh | D22: =(D21+(D21*$D$9)) -> 0 | E22: =(D22*Input!$D$5)+(365*Input!$D$7) -> 0 | F22: =Input!$D$14*G22 -> 0 | G22: =G21-0.005 -> 0.955 | H22: =Calculation!$KY$9 -> 0 | I22: =H22*D22 -> 0 | J22: =E22-I22 -> 0 | K22: =K21+I22 -> -4077.6146 | L22: =L21+I22 -> 0
B23: 11 | C23: =C22 -> kWh | D23: =(D22+(D22*$D$9)) -> 0 | E23: =(D23*Input!$D$5)+(365*Input!$D$7) -> 0 | F23: =Input!$D$14*G23 -> 0 | G23: =G22-0.005 -> 0.95 | H23: =Calculation!$KY$9 -> 0 | I23: =H23*D23 -> 0 | J23: =E23-I23 -> 0 | K23: =K22+I23 -> -4077.6146 | L23: =L22+I23 -> 0
B24: 12 | C24: =C23 -> kWh | D24: =(D23+(D23*$D$9)) -> 0 | E24: =(D24*Input!$D$5)+(365*Input!$D$7) -> 0 | F24: =Input!$D$14*G24 -> 0 | G24: =G23-0.005 -> 0.945 | H24: =Calculation!$KY$9 -> 0 | I24: =H24*D24 -> 0 | J24: =E24-I24 -> 0 | K24: =K23+I24 -> -4077.6146 | L24: =L23+I24 -> 0
B25: 13 | C25: =C24 -> kWh | D25: =(D24+(D24*$D$9)) -> 0 | E25: =(D25*Input!$D$5)+(365*Input!$D$7) -> 0 | F25: =Input!$D$14*G25 -> 0 | G25: =G24-0.005 -> 0.94 | H25: =Calculation!$KY$9 -> 0 | I25: =H25*D25 -> 0 | J25: =E25-I25 -> 0 | K25: =K24+I25 -> -4077.6146 | L25: =L24+I25 -> 0
... B32: 20 | C32: =C31 -> kWh | D32: =(D31+(D31*$D$9)) -> 0 | E32: =(D32*Input!$D$5)+(365*Input!$D$7) -> 0 | F32: =Input!$D$14*G32 -> 0 | G32: =G31-0.005 -> 0.905 | H32: =Calculation!$KY$9 -> 0 | I32: =H32*D32 -> 0 | J32: =E32-I32 -> 0 | K32: =K31+I32 -> -4077.6146 | L32: =L31+I32 -> 0

Sheet Profile
A1: Date | B1: Day | C1: Half Hour | D1: HH Period | E1: Solar Coefficient | F1: Consumption Coefficient
A2: 43466 | B2: 1 | C2: 1 | D2: 0 | E2: 0 | F2: 6.0793852e-05
A3: 43466 | B3: 1 | C3: 2 | D3: 0.020833333 | E3: 0 | F3: 5.5385503e-05
A4: 43466 | B4: 1 | C4: 3 | D4: 0.041666667 | E4: 0 | F4: 5.2881637e-05
A5: 43466 | B5: 1 | C5: 4 | D5: 0.0625 | E5: 0 | F5: 4.9876999e-05
A6: 43466 | B6: 1 | C6: 5 | D6: 0.083333333 | E6: 0 | F6: 4.9075762e-05
A7: 43466 | B7: 1 | C7: 6 | D7: 0.10416667 | E7: 0 | F7: 4.1764475e-05
A8: 43466 | B8: 1 | C8: 7 | D8: 0.125 | E8: 0 | F8: 3.8960146e-05
A9: 43466 | B9: 1 | C9: 8 | D9: 0.14583333 | E9: 0 | F9: 3.5955507e-05
A10: 43466 | B10: 1 | C10: 9 | D10: 0.16666667 | E10: 0 | F10: 3.4653497e-05
A11: 43466 | B11: 1 | C11: 10 | D11: 0.1875 | E11: 0 | F11: 3.4152724e-05
A12: 43466 | B12: 1 | C12: 11 | D12: 0.20833333 | E12: 0 | F12: 3.4553343e-05
A13: 43466 | B13: 1 | C13: 12 | D13: 0.22916667 | E13: 0 | F13: 3.5054116e-05
... A17521: 43830 | B17521: 365 | C17521: 48 | D17521: 0.97916667 | E17521: 0 | F17521: 5.5685967e-05

Sheet Calculation
KM1: 1 | KN1: 2 | KO1: 3 | KP1: 4 | KQ1: 5 | KR1: 6 | KS1: 7 | KT1: 8 | KU1: 9 | KV1: 10 | KW1: 11 | KX1: 12
KM2: Jan | KN2: Feb | KO2: Mar | KP2: Apr | KQ2: May | KR2: Jun | KS2: Jul | KT2: Aug | KU2: Sep | KV2: Oct | KW2: Nov | KX2: Dec | KY2: Total
KL3: Demand | KM3: =SUMIF($A$11:$A$375,KM$1,$D$11:$D$375) -> 0 | KN3: =SUMIF($A$11:$A$375,KN$1,$D$11:$D$375) -> 0 | KO3: =SUMIF($A$11:$A$375,KO$1,$D$11:$D$375) -> 0 | KP3: =SUMIF($A$11:$A$375,KP$1,$D$11:$D$375) -> 0 | KQ3: =SUMIF($A$11:$A$375,KQ$1,$D$11:$D$375) -> 0 | KR3: =SUMIF($A$11:$A$375,KR$1,$D$11:$D$375) -> 0 | KS3: =SUMIF($A$11:$A$375,KS$1,$D$11:$D$375) -> 0 | KT3: =SUMIF($A$11:$A$375,KT$1,$D$11:$D$375) -> 0 | ... KX3: =SUMIF($A$11:$A$375,KX$1,$D$11:$D$375) -> 0 | KY3: =SUM(KM3:KX3) -> 0
KL4: Solar | KM4: =SUMIF($A$11:$A$375,KM$1,$BA$11:$BA$375) -> 0 | KN4: =SUMIF($A$11:$A$375,KN$1,$BA$11:$BA$375) -> 0 | KO4: =SUMIF($A$11:$A$375,KO$1,$BA$11:$BA$375) -> 0 | KP4: =SUMIF($A$11:$A$375,KP$1,$BA$11:$BA$375) -> 0 | KQ4: =SUMIF($A$11:$A$375,KQ$1,$BA$11:$BA$375) -> 0 | KR4: =SUMIF($A$11:$A$375,KR$1,$BA$11:$BA$375) -> 0 | KS4: =SUMIF($A$11:$A$375,KS$1,$BA$11:$BA$375) -> 0 | KT4: =SUMIF($A$11:$A$375,KT$1,$BA$11:$BA$375) -> 0 | ... KX4: =SUMIF($A$11:$A$375,KX$1,$BA$11:$BA$375) -> 0 | KY4: =SUM(KM4:KX4) -> 0
BA5: Total Self Consumption without Battery | CX5: =EU8 -> 0 | EU5: =CX5/BA8 -> #DIV/0! | KL5: Export | KM5: =SUMIF($A$11:$A$375,KM$1,$CX$11:$CX$375) -> 0 | KN5: =SUMIF($A$11:$A$375,KN$1,$CX$11:$CX$375) -> 0 | KO5: =SUMIF($A$11:$A$375,KO$1,$CX$11:$CX$375) -> 0 | KP5: =SUMIF($A$11:$A$375,KP$1,$CX$11:$CX$375) -> 0 | KQ5: =SUMIF($A$11:$A$375,KQ$1,$CX$11:$CX$375) -> 0 | KR5: =SUMIF($A$11:$A$375,KR$1,$CX$11:$CX$375) -> 0 | KS5: =SUMIF($A$11:$A$375,KS$1,$CX$11:$CX$375) -> 0 | KT5: =SUMIF($A$11:$A$375,KT$1,$CX$11:$CX$375) -> 0 | ... KX5: =SUMIF($A$11:$A$375,KX$1,$CX$11:$CX$375) -> 0 | KY5: =SUM(KM5:KX5) -> 0
B6: Demand (Annual kWh) | C6: =Input!D5 | BA6: Total Self Consumption With Battery | CX6: =CX5+IO8 -> 0 | EU6: =CX6/BA8 -> #DIV/0! | KL6: Self Consumption Without Battery | KM6: =SUMIF($A$11:$A$375,KM$1,$EU$11:$EU$375) -> 0 | KN6: =SUMIF($A$11:$A$375,KN$1,$EU$11:$EU$375) -> 0 | KO6: =SUMIF($A$11:$A$375,KO$1,$EU$11:$EU$375) -> 0 | KP6: =SUMIF($A$11:$A$375,KP$1,$EU$11:$EU$375) -> 0 | KQ6: =SUMIF($A$11:$A$375,KQ$1,$EU$11:$EU$375) -> 0 | KR6: =SUMIF($A$11:$A$375,KR$1,$EU$11:$EU$375) -> 0 | KS6: =SUMIF($A$11:$A$375,KS$1,$EU$11:$EU$375) -> 0 | KT6: =SUMIF($A$11:$A$375,KT$1,$EU$11:$EU$375) -> 0 | ... KX6: =SUMIF($A$11:$A$375,KX$1,$EU$11:$EU$375) -> 0 | KY6: =SUM(KM6:KX6) -> 0 | KZ6: =KY6/KY4 -> #DIV/0!
B7: System Size (kWdc) | C7: =Input!D12 -> 2.7 | BA7: Export After Battery | CX7: =IO8 -> 0 | EU7: =CX7/BA8 -> #DIV/0! | GR7: Battery Size | IO7: =Input!D21 -> 0 | KL7: Demand After Solar | KM7: =SUMIF($A$11:$A$375,KM$1,$GR$11:$GR$375) -> 0 | KN7: =SUMIF($A$11:$A$375,KN$1,$GR$11:$GR$375) -> 0 | KO7: =SUMIF($A$11:$A$375,KO$1,$GR$11:$GR$375) -> 0 | KP7: =SUMIF($A$11:$A$375,KP$1,$GR$11:$GR$375) -> 0 | KQ7: =SUMIF($A$11:$A$375,KQ$1,$GR$11:$GR$375) -> 0 | KR7: =SUMIF($A$11:$A$375,KR$1,$GR$11:$GR$375) -> 0 | KS7: =SUMIF($A$11:$A$375,KS$1,$GR$11:$GR$375) -> 0 | KT7: =SUMIF($A$11:$A$375,KT$1,$GR$11:$GR$375) -> 0 | ... KX7: =SUMIF($A$11:$A$375,KX$1,$GR$11:$GR$375) -> 0 | KY7: =SUM(KM7:KX7) -> 0
B8: Yield (kWhac Per kWdc) | C8: =Input!D13 | D8: =SUM(D11:D375) -> 0 | E8: 1 | F8: 2 | G8: 3 | H8: 4 | I8: 5 | J8: 6 | K8: 7 | L8: 8 | M8: 9 | N8: 10 | O8: 11 | P8: 12 | Q8: 13 | R8: 14 | S8: 15 | T8: 16 | U8: 17 | V8: 18 | W8: 19 | X8: 20 | Y8: 21 | Z8: 22 | AA8: 23 | AB8: 24 | AC8: 25 | AD8: 26 | AE8: 27 | AF8: 28 | AG8: 29 | AH8: 30 | AI8: 31 | AJ8: 32 | AK8: 33 | AL8: 34 | AM8: 35 | AN8: 36 | AO8: 37 | AP8: 38 | AQ8: 39 | AR8: 40 | AS8: 41 | AT8: 42 | AU8: 43 | AV8: 44 | AW8: 45 | AX8: 46 | AY8: 47 | AZ8: 48 | BA8: =SUM(BA11:BA375) -> 0 | BB8: 1 | BC8: 2 | BD8: 3 | BE8: 4 | BF8: 5 | BG8: 6 | BH8: 7 | BI8: 8 | BJ8: 9 | BK8: 10 | BL8: 11 | BM8: 12 | BN8: 13 | BO8: 14 | BP8: 15 | BQ8: 16 | BR8: 17 | BS8: 18 | BT8: 19 | BU8: 20 | BV8: 21 | BW8: 22 | BX8: 23 | BY8: 24 | BZ8: 25 | CA8: 26 | CB8: 27 | CC8: 28 | CD8: 29 | CE8: 30 | CF8: 31 | CG8: 32 | CH8: 33 | CI8: 34 | CJ8: 35 | CK8: 36 | CL8: 37 | CM8: 38 | CN8: 39 | CO8: 40 | CP8: 41 | CQ8: 42 | CR8: 43 | CS8: 44 | CT8: 45 | CU8: 46 | CV8: 47 | CW8: 48 | CX8: =SUM(CX11:CX375) -> 0 | CY8: 1 | CZ8: 2 | DA8: 3 | DB8: 4 | DC8: 5 | DD8: 6 | DE8: 7 | DF8: 8 | DG8: 9 | DH8: 10 | DI8: 11 | DJ8: 12 | DK8: 13 | DL8: 14 | DM8: 15 | DN8: 16 | DO8: 17 | DP8: 18 | DQ8: 19 | DR8: 20 | DS8: 21 | DT8: 22 | DU8: 23 | DV8: 24 | DW8: 25 | DX8: 26 | DY8: 27 | DZ8: 28 | EA8: 29 | EB8: 30 | EC8: 31 | ED8: 32 | EE8: 33 | EF8: 34 | EG8: 35 | EH8: 36 | EI8: 37 | EJ8: 38 | EK8: 39 | EL8: 40 | EM8: 41 | EN8: 42 | EO8: 43 | EP8: 44 | EQ8: 45 | ER8: 46 | ES8: 47 | ET8: 48 | EU8: =SUM(EU11:EU375) -> 0 | EV8: 1 | EW8: 2 | EX8: 3 | EY8: 4 | EZ8: 5 | FA8: 6 | FB8: 7 | FC8: 8 | FD8: 9 | FE8: 10 | FF8: 11 | FG8: 12 | FH8: 13 | FI8: 14 | FJ8: 15 | FK8: 16 | FL8: 17 | FM8: 18 | FN8: 19 | FO8: 20 | FP8: 21 | FQ8: 22 | FR8: 23 | FS8: 24 | FT8: 25 | FU8: 26 | FV8: 27 | FW8: 28 | FX8: 29 | FY8: 30 | FZ8: 31 | GA8: 32 | GB8: 33 | GC8: 34 | GD8: 35 | GE8: 36 | GF8: 37 | GG8: 38 | GH8: 39 | GI8: 40 | GJ8: 41 | GK8: 42 | GL8: 43 | GM8: 44 | GN8: 45 | GO8: 46 | GP8: 47 | GQ8: 48 | GR8: =SUM(GR11:GR375) -> 0 | GS8: 1 | GT8: 2 | GU8: 3 | GV8: 4 | GW8: 5 | GX8: 6 | GY8: 7 | GZ8: 8 | HA8: 9 | HB8: 10 | HC8: 11 | HD8: 12 | HE8: 13 | HF8: 14 | HG8: 15 | HH8: 16 | HI8: 17 | HJ8: 18 | HK8: 19 | HL8: 20 | HM8: 21 | HN8: 22 | HO8: 23 | HP8: 24 | HQ8: 25 | HR8: 26 | HS8: 27 | HT8: 28 | HU8: 29 | HV8: 30 | HW8: 31 | HX8: 32 | HY8: 33 | HZ8: 34 | IA8: 35 | IB8: 36 | IC8: 37 | ID8: 38 | IE8: 39 | IF8: 40 | IG8: 41 | IH8: 42 | II8: 43 | IJ8: 44 | IK8: 45 | IL8: 46 | IM8: 47 | IN8: 48 | IO8: =SUM(IO11:IO375) -> 0 | IP8: 1 | IQ8: 2 | IR8: 3 | IS8: 4 | IT8: 5 | IU8: 6 | IV8: 7 | IW8: 8 | IX8: 9 | IY8: 10 | IZ8: 11 | JA8: 12 | JB8: 13 | JC8: 14 | JD8: 15 | JE8: 16 | JF8: 17 | JG8: 18 | JH8: 19 | JI8: 20 | JJ8: 21 | JK8: 22 | JL8: 23 | JM8: 24 | JN8: 25 | JO8: 26 | JP8: 27 | JQ8: 28 | JR8: 29 | JS8: 30 | JT8: 31 | JU8: 32 | JV8: 33 | JW8: 34 | JX8: 35 | JY8: 36 | JZ8: 37 | KA8: 38 | KB8: 39 | KC8: 40 | KD8: 41 | KE8: 42 | KF8: 43 | KG8: 44 | KH8: 45 | KI8: 46 | KJ8: 47 | KK8: 48 | KL8: Export After Battery | KM8: =SUMIF($A$11:$A$375,KM$1,$IO$11:$IO$375) -> 0 | KN8: =SUMIF($A$11:$A$375,KN$1,$IO$11:$IO$375) -> 0 | KO8: =SUMIF($A$11:$A$375,KO$1,$IO$11:$IO$375) -> 0 | KP8: =SUMIF($A$11:$A$375,KP$1,$IO$11:$IO$375) -> 0 | KQ8: =SUMIF($A$11:$A$375,KQ$1,$IO$11:$IO$375) -> 0 | KR8: =SUMIF($A$11:$A$375,KR$1,$IO$11:$IO$375) -> 0 | KS8: =SUMIF($A$11:$A$375,KS$1,$IO$11:$IO$375) -> 0 | KT8: =SUMIF($A$11:$A$375,KT$1,$IO$11:$IO$375) -> 0 | ... KX8: =SUMIF($A$11:$A$375,KX$1,$IO$11:$IO$375) -> 0 | KY8: =SUM(KM8:KX8) -> 0
B9: Annual Generation (Annual kWhac) | C9: =Input!D14 -> 0 | D9: Total | E9: 0.020833333 | F9: 0.041666667 | G9: 0.0625 | H9: 0.083333333 | I9: 0.10416667 | J9: 0.125 | K9: 0.14583333 | L9: 0.16666667 | M9: 0.1875 | N9: 0.20833333 | O9: 0.22916667 | P9: 0.25 | Q9: 0.27083333 | R9: 0.29166667 | S9: 0.3125 | T9: 0.33333333 | U9: 0.35416667 | V9: 0.375 | W9: 0.39583333 | X9: 0.41666667 | Y9: 0.4375 | Z9: 0.45833333 | AA9: 0.47916667 | AB9: 0.5 | AC9: 0.52083333 | AD9: 0.54166667 | AE9: 0.5625 | AF9: 0.58333333 | AG9: 0.60416667 | AH9: 0.625 | AI9: 0.64583333 | AJ9: 0.66666667 | AK9: 0.6875 | AL9: 0.70833333 | AM9: 0.72916667 | AN9: 0.75 | AO9: 0.77083333 | AP9: 0.79166667 | AQ9: 0.8125 | AR9: 0.83333333 | AS9: 0.85416667 | AT9: 0.875 | AU9: 0.89583333 | AV9: 0.91666667 | AW9: 0.9375 | AX9: 0.95833333 | AY9: 0.97916667 | AZ9: 1 | BA9: Total | BB9: 0.020833333 | BC9: 0.041666667 | BD9: 0.0625 | BE9: 0.083333333 | BF9: 0.10416667 | BG9: 0.125 | BH9: 0.14583333 | BI9: 0.16666667 | BJ9: 0.1875 | BK9: 0.20833333 | BL9: 0.22916667 | BM9: 0.25 | BN9: 0.27083333 | BO9: 0.29166667 | BP9: 0.3125 | BQ9: 0.33333333 | BR9: 0.35416667 | BS9: 0.375 | BT9: 0.39583333 | BU9: 0.41666667 | BV9: 0.4375 | BW9: 0.45833333 | BX9: 0.47916667 | BY9: 0.5 | BZ9: 0.52083333 | CA9: 0.54166667 | CB9: 0.5625 | CC9: 0.58333333 | CD9: 0.60416667 | CE9: 0.625 | CF9: 0.64583333 | CG9: 0.66666667 | CH9: 0.6875 | CI9: 0.70833333 | CJ9: 0.72916667 | CK9: 0.75 | CL9: 0.77083333 | CM9: 0.79166667 | CN9: 0.8125 | CO9: 0.83333333 | CP9: 0.85416667 | CQ9: 0.875 | CR9: 0.89583333 | CS9: 0.91666667 | CT9: 0.9375 | CU9: 0.95833333 | CV9: 0.97916667 | CW9: 1 | CX9: Total | CY9: 0.020833333 | CZ9: 0.041666667 | DA9: 0.0625 | DB9: 0.083333333 | DC9: 0.10416667 | DD9: 0.125 | DE9: 0.14583333 | DF9: 0.16666667 | DG9: 0.1875 | DH9: 0.20833333 | DI9: 0.22916667 | DJ9: 0.25 | DK9: 0.27083333 | DL9: 0.29166667 | DM9: 0.3125 | DN9: 0.33333333 | DO9: 0.35416667 | DP9: 0.375 | DQ9: 0.39583333 | DR9: 0.41666667 | DS9: 0.4375 | DT9: 0.45833333 | DU9: 0.47916667 | DV9: 0.5 | DW9: 0.52083333 | DX9: 0.54166667 | DY9: 0.5625 | DZ9: 0.58333333 | EA9: 0.60416667 | EB9: 0.625 | EC9: 0.64583333 | ED9: 0.66666667 | EE9: 0.6875 | EF9: 0.70833333 | EG9: 0.72916667 | EH9: 0.75 | EI9: 0.77083333 | EJ9: 0.79166667 | EK9: 0.8125 | EL9: 0.83333333 | EM9: 0.85416667 | EN9: 0.875 | EO9: 0.89583333 | EP9: 0.91666667 | EQ9: 0.9375 | ER9: 0.95833333 | ES9: 0.97916667 | ET9: 1 | EU9: Total | EV9: 0.020833333 | EW9: 0.041666667 | EX9: 0.0625 | EY9: 0.083333333 | EZ9: 0.10416667 | FA9: 0.125 | FB9: 0.14583333 | FC9: 0.16666667 | FD9: 0.1875 | FE9: 0.20833333 | FF9: 0.22916667 | FG9: 0.25 | FH9: 0.27083333 | FI9: 0.29166667 | FJ9: 0.3125 | FK9: 0.33333333 | FL9: 0.35416667 | FM9: 0.375 | FN9: 0.39583333 | FO9: 0.41666667 | FP9: 0.4375 | FQ9: 0.45833333 | FR9: 0.47916667 | FS9: 0.5 | FT9: 0.52083333 | FU9: 0.54166667 | FV9: 0.5625 | FW9: 0.58333333 | FX9: 0.60416667 | FY9: 0.625 | FZ9: 0.64583333 | GA9: 0.66666667 | GB9: 0.6875 | GC9: 0.70833333 | GD9: 0.72916667 | GE9: 0.75 | GF9: 0.77083333 | GG9: 0.79166667 | GH9: 0.8125 | GI9: 0.83333333 | GJ9: 0.85416667 | GK9: 0.875 | GL9: 0.89583333 | GM9: 0.91666667 | GN9: 0.9375 | GO9: 0.95833333 | GP9: 0.97916667 | GQ9: 1 | GR9: Total | GS9: 0.020833333 | GT9: 0.041666667 | GU9: 0.0625 | GV9: 0.083333333 | GW9: 0.10416667 | GX9: 0.125 | GY9: 0.14583333 | GZ9: 0.16666667 | HA9: 0.1875 | HB9: 0.20833333 | HC9: 0.22916667 | HD9: 0.25 | HE9: 0.27083333 | HF9: 0.29166667 | HG9: 0.3125 | HH9: 0.33333333 | HI9: 0.35416667 | HJ9: 0.375 | HK9: 0.39583333 | HL9: 0.41666667 | HM9: 0.4375 | HN9: 0.45833333 | HO9: 0.47916667 | HP9: 0.5 | HQ9: 0.52083333 | HR9: 0.54166667 | HS9: 0.5625 | HT9: 0.58333333 | HU9: 0.60416667 | HV9: 0.625 | HW9: 0.64583333 | HX9: 0.66666667 | HY9: 0.6875 | HZ9: 0.70833333 | IA9: 0.72916667 | IB9: 0.75 | IC9: 0.77083333 | ID9: 0.79166667 | IE9: 0.8125 | IF9: 0.83333333 | IG9: 0.85416667 | IH9: 0.875 | II9: 0.89583333 | IJ9: 0.91666667 | IK9: 0.9375 | IL9: 0.95833333 | IM9: 0.97916667 | IN9: 1 | IO9: Total | IP9: 0.020833333 | IQ9: 0.041666667 | IR9: 0.0625 | IS9: 0.083333333 | IT9: 0.10416667 | IU9: 0.125 | IV9: 0.14583333 | IW9: 0.16666667 | IX9: 0.1875 | IY9: 0.20833333 | IZ9: 0.22916667 | JA9: 0.25 | JB9: 0.27083333 | JC9: 0.29166667 | JD9: 0.3125 | JE9: 0.33333333 | JF9: 0.35416667 | JG9: 0.375 | JH9: 0.39583333 | JI9: 0.41666667 | JJ9: 0.4375 | JK9: 0.45833333 | JL9: 0.47916667 | JM9: 0.5 | JN9: 0.52083333 | JO9: 0.54166667 | JP9: 0.5625 | JQ9: 0.58333333 | JR9: 0.60416667 | JS9: 0.625 | JT9: 0.64583333 | JU9: 0.66666667 | JV9: 0.6875 | JW9: 0.70833333 | JX9: 0.72916667 | JY9: 0.75 | JZ9: 0.77083333 | KA9: 0.79166667 | KB9: 0.8125 | KC9: 0.83333333 | KD9: 0.85416667 | KE9: 0.875 | KF9: 0.89583333 | KG9: 0.91666667 | KH9: 0.9375 | KI9: 0.95833333 | KJ9: 0.97916667 | KK9: 1 | KL9: Total Self Consumption With Battery | KM9: =SUMIF($A$11:$A$375,KM$1,$IO$11:$IO$375)+KM6 -> 0 | KN9: =SUMIF($A$11:$A$375,KN$1,$IO$11:$IO$375)+KN6 -> 0 | KO9: =SUMIF($A$11:$A$375,KO$1,$IO$11:$IO$375)+KO6 -> 0 | KP9: =SUMIF($A$11:$A$375,KP$1,$IO$11:$IO$375)+KP6 -> 0 | KQ9: =SUMIF($A$11:$A$375,KQ$1,$IO$11:$IO$375)+KQ6 -> 0 | KR9: =SUMIF($A$11:$A$375,KR$1,$IO$11:$IO$375)+KR6 -> 0 | KS9: =SUMIF($A$11:$A$375,KS$1,$IO$11:$IO$375)+KS6 -> 0 | KT9: =SUMIF($A$11:$A$375,KT$1,$IO$11:$IO$375)+KT6 -> 0 | ... KX9: =SUMIF($A$11:$A$375,KX$1,$IO$11:$IO$375)+KX6 -> 0 | KY9: =SUM(KM9:KX9) -> 0 | KZ9: =KY9/KY4 -> #DIV/0!
A10: Count (Month) | B10: Count (Day) | C10: Date | D10: Demand | E10: Demand | F10: Demand | G10: Demand | H10: Demand | I10: Demand | J10: Demand | K10: Demand | L10: Demand | M10: Demand | N10: Demand | O10: Demand | P10: Demand | Q10: Demand | R10: Demand | S10: Demand | T10: Demand | U10: Demand | V10: Demand | W10: Demand | X10: Demand | Y10: Demand | Z10: Demand | AA10: Demand | AB10: Demand | AC10: Demand | AD10: Demand | AE10: Demand | AF10: Demand | AG10: Demand | AH10: Demand | AI10: Demand | AJ10: Demand | AK10: Demand | AL10: Demand | AM10: Demand | AN10: Demand | AO10: Demand | AP10: Demand | AQ10: Demand | AR10: Demand | AS10: Demand | AT10: Demand | AU10: Demand | AV10: Demand | AW10: Demand | AX10: Demand | AY10: Demand | AZ10: Demand | BA10: Solar | BB10: Solar | BC10: Solar | BD10: Solar | BE10: Solar | BF10: Solar | BG10: Solar | BH10: Solar | BI10: Solar | BJ10: Solar | BK10: Solar | BL10: Solar | BM10: Solar | BN10: Solar | BO10: Solar | BP10: Solar | BQ10: Solar | BR10: Solar | BS10: Solar | BT10: Solar | BU10: Solar | BV10: Solar | BW10: Solar | BX10: Solar | BY10: Solar | BZ10: Solar | CA10: Solar | CB10: Solar | CC10: Solar | CD10: Solar | CE10: Solar | CF10: Solar | CG10: Solar | CH10: Solar | CI10: Solar | CJ10: Solar | CK10: Solar | CL10: Solar | CM10: Solar | CN10: Solar | CO10: Solar | CP10: Solar | CQ10: Solar | CR10: Solar | CS10: Solar | CT10: Solar | CU10: Solar | CV10: Solar | CW10: Solar | CX10: Export | CY10: Export | CZ10: Export | DA10: Export | DB10: Export | DC10: Export | DD10: Export | DE10: Export | DF10: Export | DG10: Export | DH10: Export | DI10: Export | DJ10: Export | DK10: Export | DL10: Export | DM10: Export | DN10: Export | DO10: Export | DP10: Export | DQ10: Export | DR10: Export | DS10: Export | DT10: Export | DU10: Export | DV10: Export | DW10: Export | DX10: Export | DY10: Export | DZ10: Export | EA10: Export | EB10: Export | EC10: Export | ED10: Export | EE10: Export | EF10: Export | EG10: Export | EH10: Export | EI10: Export | EJ10: Export | EK10: Export | EL10: Export | EM10: Export | EN10: Export | EO10: Export | EP10: Export | EQ10: Export | ER10: Export | ES10: Export | ET10: Export | EU10: Self Consumption | EV10: Self Consumption | EW10: Self Consumption | EX10: Self Consumption | EY10: Self Consumption | EZ10: Self Consumption | FA10: Self Consumption | FB10: Self Consumption | FC10: Self Consumption | FD10: Self Consumption | FE10: Self Consumption | FF10: Self Consumption | FG10: Self Consumption | FH10: Self Consumption | FI10: Self Consumption | FJ10: Self Consumption | FK10: Self Consumption | FL10: Self Consumption | FM10: Self Consumption | FN10: Self Consumption | FO10: Self Consumption | FP10: Self Consumption | FQ10: Self Consumption | FR10: Self Consumption | FS10: Self Consumption | FT10: Self Consumption | FU10: Self Consumption | FV10: Self Consumption | FW10: Self Consumption | FX10: Self Consumption | FY10: Self Consumption | FZ10: Self Consumption | GA10: Self Consumption | GB10: Self Consumption | GC10: Self Consumption | GD10: Self Consumption | GE10: Self Consumption | GF10: Self Consumption | GG10: Self Consumption | GH10: Self Consumption | GI10: Self Consumption | GJ10: Self Consumption | GK10: Self Consumption | GL10: Self Consumption | GM10: Self Consumption | GN10: Self Consumption | GO10: Self Consumption | GP10: Self Consumption | GQ10: Self Consumption | GR10: Demand After Solar | GS10: Demand After Self Consumption of Solar | GT10: Demand After Self Consumption of Solar | GU10: Demand After Self Consumption of Solar | GV10: Demand After Self Consumption of Solar | GW10: Demand After Self Consumption of Solar | GX10: Demand After Self Consumption of Solar | GY10: Demand After Self Consumption of Solar | GZ10: Demand After Self Consumption of Solar | HA10: Demand After Self Consumption of Solar | HB10: Demand After Self Consumption of Solar | HC10: Demand After Self Consumption of Solar | HD10: Demand After Self Consumption of Solar | HE10: Demand After Self Consumption of Solar | HF10: Demand After Self Consumption of Solar | HG10: Demand After Self Consumption of Solar | HH10: Demand After Self Consumption of Solar | HI10: Demand After Self Consumption of Solar | HJ10: Demand After Self Consumption of Solar | HK10: Demand After Self Consumption of Solar | HL10: Demand After Self Consumption of Solar | HM10: Demand After Self Consumption of Solar | HN10: Demand After Self Consumption of Solar | HO10: Demand After Self Consumption of Solar | HP10: Demand After Self Consumption of Solar | HQ10: Demand After Self Consumption of Solar | HR10: Demand After Self Consumption of Solar | HS10: Demand After Self Consumption of Solar | HT10: Demand After Self Consumption of Solar | HU10: Demand After Self Consumption of Solar | HV10: Demand After Self Consumption of Solar | HW10: Demand After Self Consumption of Solar | HX10: Demand After Self Consumption of Solar | HY10: Demand After Self Consumption of Solar | HZ10: Demand After Self Consumption of Solar | IA10: Demand After Self Consumption of Solar | IB10: Demand After Self Consumption of Solar | IC10: Demand After Self Consumption of Solar | ID10: Demand After Self Consumption of Solar | IE10: Demand After Self Consumption of Solar | IF10: Demand After Self Consumption of Solar | IG10: Demand After Self Consumption of Solar | IH10: Demand After Self Consumption of Solar | II10: Demand After Self Consumption of Solar | IJ10: Demand After Self Consumption of Solar | IK10: Demand After Self Consumption of Solar | IL10: Demand After Self Consumption of Solar | IM10: Demand After Self Consumption of Solar | IN10: Demand After Self Consumption of Solar | IO10: Battery Use | IP10: Battey Charge / Discharge | IQ10: Battey Charge / Discharge | IR10: Battey Charge / Discharge | IS10: Battey Charge / Discharge | IT10: Battey Charge / Discharge | IU10: Battey Charge / Discharge | IV10: Battey Charge / Discharge | IW10: Battey Charge / Discharge | IX10: Battey Charge / Discharge | IY10: Battey Charge / Discharge | IZ10: Battey Charge / Discharge | JA10: Battey Charge / Discharge | JB10: Battey Charge / Discharge | JC10: Battey Charge / Discharge | JD10: Battey Charge / Discharge | JE10: Battey Charge / Discharge | JF10: Battey Charge / Discharge | JG10: Battey Charge / Discharge | JH10: Battey Charge / Discharge | JI10: Battey Charge / Discharge | JJ10: Battey Charge / Discharge | JK10: Battey Charge / Discharge | JL10: Battey Charge / Discharge | JM10: Battey Charge / Discharge | JN10: Battey Charge / Discharge | JO10: Battey Charge / Discharge | JP10: Battey Charge / Discharge | JQ10: Battey Charge / Discharge | JR10: Battey Charge / Discharge | JS10: Battey Charge / Discharge | JT10: Battey Charge / Discharge | JU10: Battey Charge / Discharge | JV10: Battey Charge / Discharge | JW10: Battey Charge / Discharge | JX10: Battey Charge / Discharge | JY10: Battey Charge / Discharge | JZ10: Battey Charge / Discharge | KA10: Battey Charge / Discharge | KB10: Battey Charge / Discharge | KC10: Battey Charge / Discharge | KD10: Battey Charge / Discharge | KE10: Battey Charge / Discharge | KF10: Battey Charge / Discharge | KG10: Battey Charge / Discharge | KH10: Battey Charge / Discharge | KI10: Battey Charge / Discharge | KJ10: Battey Charge / Discharge | KK10: Battey Charge / Discharge | KL10: Demand After Solar and Storage | KM10: =KM3-KM9 -> 0 | KN10: =KN3-KN9 -> 0 | KO10: =KO3-KO9 -> 0 | KP10: =KP3-KP9 -> 0 | KQ10: =KQ3-KQ9 -> 0 | KR10: =KR3-KR9 -> 0 | KS10: =KS3-KS9 -> 0 | KT10: =KT3-KT9 -> 0 | ... KX10: =KX3-KX9 -> 0 | KY10: =SUM(KM10:KX10) -> 0
